2020-07-21 20:22:52 - root - INFO - Connection with MYSQL ready
2020-07-21 20:22:52 - root - INFO - Database was created successfully
2020-07-21 20:23:06 - root - INFO - Tables were created successfully
2020-07-21 20:24:18 - root - INFO - Browser connect to URL
2020-07-21 20:24:21 - root - INFO - Search for job title
2020-07-21 20:24:22 - root - INFO - Search for job location
2020-07-21 20:24:30 - root - ERROR - No popup to close
Traceback (most recent call last):
  File "/Users/Sheryl/PycharmProjects/Itc_data_mining/scraper.py", line 29, in close_popup
    pop_up = self.browser.find_element_by_xpath(self.config['Path']['POP_UP_XPATH'])
  File "/Users/Sheryl/PycharmProjects/Itc_data_mining/data_mining/lib/python3.6/site-packages/selenium/webdriver/remote/webdriver.py", line 394, in find_element_by_xpath
    return self.find_element(by=By.XPATH, value=xpath)
  File "/Users/Sheryl/PycharmProjects/Itc_data_mining/data_mining/lib/python3.6/site-packages/selenium/webdriver/remote/webdriver.py", line 978, in find_element
    'value': value})['value']
  File "/Users/Sheryl/PycharmProjects/Itc_data_mining/data_mining/lib/python3.6/site-packages/selenium/webdriver/remote/webdriver.py", line 321, in execute
    self.error_handler.check_response(response)
  File "/Users/Sheryl/PycharmProjects/Itc_data_mining/data_mining/lib/python3.6/site-packages/selenium/webdriver/remote/errorhandler.py", line 242, in check_response
    raise exception_class(message, screen, stacktrace)
selenium.common.exceptions.NoSuchElementException: Message: Unable to locate element: //div[contains(@class,'modal_main')]//span[@class='SVGInline modal_closeIcon']

2020-07-21 20:24:44 - root - INFO - Browser connect to new URL
2020-07-21 20:25:01 - root - ERROR - No popup to close
Traceback (most recent call last):
  File "/Users/Sheryl/PycharmProjects/Itc_data_mining/scraper.py", line 29, in close_popup
    pop_up = self.browser.find_element_by_xpath(self.config['Path']['POP_UP_XPATH'])
  File "/Users/Sheryl/PycharmProjects/Itc_data_mining/data_mining/lib/python3.6/site-packages/selenium/webdriver/remote/webdriver.py", line 394, in find_element_by_xpath
    return self.find_element(by=By.XPATH, value=xpath)
  File "/Users/Sheryl/PycharmProjects/Itc_data_mining/data_mining/lib/python3.6/site-packages/selenium/webdriver/remote/webdriver.py", line 978, in find_element
    'value': value})['value']
  File "/Users/Sheryl/PycharmProjects/Itc_data_mining/data_mining/lib/python3.6/site-packages/selenium/webdriver/remote/webdriver.py", line 321, in execute
    self.error_handler.check_response(response)
  File "/Users/Sheryl/PycharmProjects/Itc_data_mining/data_mining/lib/python3.6/site-packages/selenium/webdriver/remote/errorhandler.py", line 242, in check_response
    raise exception_class(message, screen, stacktrace)
selenium.common.exceptions.NoSuchElementException: Message: Unable to locate element: //div[contains(@class,'modal_main')]//span[@class='SVGInline modal_closeIcon']

2020-07-21 20:25:03 - root - INFO - Succeed to catch number of available pages
2020-07-21 20:25:21 - root - INFO - Succeed to close popup'
2020-07-21 20:25:21 - root - INFO - Start to collect all data from page
2020-07-21 20:26:07 - root - ERROR - There is a problem with catching text from xpath
Traceback (most recent call last):
  File "/Users/Sheryl/PycharmProjects/Itc_data_mining/scraper.py", line 43, in catch_optional_text_value_by_xpath
    text_value = self.browser.find_element_by_xpath(x_path).text
  File "/Users/Sheryl/PycharmProjects/Itc_data_mining/data_mining/lib/python3.6/site-packages/selenium/webdriver/remote/webdriver.py", line 394, in find_element_by_xpath
    return self.find_element(by=By.XPATH, value=xpath)
  File "/Users/Sheryl/PycharmProjects/Itc_data_mining/data_mining/lib/python3.6/site-packages/selenium/webdriver/remote/webdriver.py", line 978, in find_element
    'value': value})['value']
  File "/Users/Sheryl/PycharmProjects/Itc_data_mining/data_mining/lib/python3.6/site-packages/selenium/webdriver/remote/webdriver.py", line 321, in execute
    self.error_handler.check_response(response)
  File "/Users/Sheryl/PycharmProjects/Itc_data_mining/data_mining/lib/python3.6/site-packages/selenium/webdriver/remote/errorhandler.py", line 242, in check_response
    raise exception_class(message, screen, stacktrace)
selenium.common.exceptions.NoSuchElementException: Message: Unable to locate element: //div[@class="infoEntity"]//label[text()="Competitors"]//following-sibling::*

2020-07-21 20:26:10 - root - INFO - Insert company to DB successfully
2020-07-21 20:26:11 - root - INFO - Insert job to DB successfully
2020-07-21 20:26:46 - root - INFO - Insert company to DB successfully
2020-07-21 20:26:46 - root - INFO - Insert job to DB successfully
2020-07-21 20:26:54 - urllib3.connectionpool - WARNING - Retrying (Retry(total=2, connect=None, read=None, redirect=None, status=None)) after connection broken by 'NewConnectionError('<urllib3.connection.HTTPConnection object at 0x1037a2f98>: Failed to establish a new connection: [Errno 61] Connection refused',)': /session/cdd08230-1c7d-a24d-8d2f-08642eb897e5/element/fb23e27f-bafa-ba41-8b54-264f06aa9479/click
2020-07-21 20:26:54 - urllib3.connectionpool - WARNING - Retrying (Retry(total=1, connect=None, read=None, redirect=None, status=None)) after connection broken by 'NewConnectionError('<urllib3.connection.HTTPConnection object at 0x10380f630>: Failed to establish a new connection: [Errno 61] Connection refused',)': /session/cdd08230-1c7d-a24d-8d2f-08642eb897e5/element/fb23e27f-bafa-ba41-8b54-264f06aa9479/click
2020-07-21 20:26:54 - urllib3.connectionpool - WARNING - Retrying (Retry(total=0, connect=None, read=None, redirect=None, status=None)) after connection broken by 'NewConnectionError('<urllib3.connection.HTTPConnection object at 0x10380f8d0>: Failed to establish a new connection: [Errno 61] Connection refused',)': /session/cdd08230-1c7d-a24d-8d2f-08642eb897e5/element/fb23e27f-bafa-ba41-8b54-264f06aa9479/click
