2020-07-20 18:26:35 - root - INFO - Connection with MYSQL ready
2020-07-20 18:26:35 - root - INFO - Database was created successfully
2020-07-20 18:26:36 - root - INFO - Tables were created successfully
2020-07-20 18:26:48 - root - INFO - Browser connect to URL
2020-07-20 18:26:51 - root - INFO - Search for job title
2020-07-20 18:26:51 - root - INFO - Search for job location
2020-07-20 18:26:59 - root - ERROR - No popup to close
Traceback (most recent call last):
  File "/Users/Sheryl/PycharmProjects/Itc_data_mining/scraper.py", line 28, in close_popup
    pop_up = self.browser.find_element_by_xpath(cst.POP_UP_XPATH)
  File "/Users/Sheryl/PycharmProjects/Itc_data_mining/data_mining/lib/python3.6/site-packages/selenium/webdriver/remote/webdriver.py", line 394, in find_element_by_xpath
    return self.find_element(by=By.XPATH, value=xpath)
  File "/Users/Sheryl/PycharmProjects/Itc_data_mining/data_mining/lib/python3.6/site-packages/selenium/webdriver/remote/webdriver.py", line 978, in find_element
    'value': value})['value']
  File "/Users/Sheryl/PycharmProjects/Itc_data_mining/data_mining/lib/python3.6/site-packages/selenium/webdriver/remote/webdriver.py", line 321, in execute
    self.error_handler.check_response(response)
  File "/Users/Sheryl/PycharmProjects/Itc_data_mining/data_mining/lib/python3.6/site-packages/selenium/webdriver/remote/errorhandler.py", line 242, in check_response
    raise exception_class(message, screen, stacktrace)
selenium.common.exceptions.NoSuchElementException: Message: Unable to locate element: //div[contains(@class,'modal_main')]//span[@class='SVGInline modal_closeIcon']

2020-07-20 18:27:10 - root - INFO - Browser connect to new URL
2020-07-20 18:27:26 - root - ERROR - No popup to close
Traceback (most recent call last):
  File "/Users/Sheryl/PycharmProjects/Itc_data_mining/scraper.py", line 28, in close_popup
    pop_up = self.browser.find_element_by_xpath(cst.POP_UP_XPATH)
  File "/Users/Sheryl/PycharmProjects/Itc_data_mining/data_mining/lib/python3.6/site-packages/selenium/webdriver/remote/webdriver.py", line 394, in find_element_by_xpath
    return self.find_element(by=By.XPATH, value=xpath)
  File "/Users/Sheryl/PycharmProjects/Itc_data_mining/data_mining/lib/python3.6/site-packages/selenium/webdriver/remote/webdriver.py", line 978, in find_element
    'value': value})['value']
  File "/Users/Sheryl/PycharmProjects/Itc_data_mining/data_mining/lib/python3.6/site-packages/selenium/webdriver/remote/webdriver.py", line 321, in execute
    self.error_handler.check_response(response)
  File "/Users/Sheryl/PycharmProjects/Itc_data_mining/data_mining/lib/python3.6/site-packages/selenium/webdriver/remote/errorhandler.py", line 242, in check_response
    raise exception_class(message, screen, stacktrace)
selenium.common.exceptions.NoSuchElementException: Message: Unable to locate element: //div[contains(@class,'modal_main')]//span[@class='SVGInline modal_closeIcon']

2020-07-20 18:27:26 - root - INFO - Succeed to catch number of available pages
2020-07-20 18:27:37 - root - INFO - Succeed to close popup
2020-07-20 18:27:37 - root - INFO - Start to collect all data from page
2020-07-20 18:28:04 - root - ERROR - There is a problem with catching text from xpath
Traceback (most recent call last):
  File "/Users/Sheryl/PycharmProjects/Itc_data_mining/scraper.py", line 42, in catch_optional_text_value_by_xpath
    """
  File "/Users/Sheryl/PycharmProjects/Itc_data_mining/data_mining/lib/python3.6/site-packages/selenium/webdriver/remote/webdriver.py", line 394, in find_element_by_xpath
    return self.find_element(by=By.XPATH, value=xpath)
  File "/Users/Sheryl/PycharmProjects/Itc_data_mining/data_mining/lib/python3.6/site-packages/selenium/webdriver/remote/webdriver.py", line 978, in find_element
    'value': value})['value']
  File "/Users/Sheryl/PycharmProjects/Itc_data_mining/data_mining/lib/python3.6/site-packages/selenium/webdriver/remote/webdriver.py", line 321, in execute
    self.error_handler.check_response(response)
  File "/Users/Sheryl/PycharmProjects/Itc_data_mining/data_mining/lib/python3.6/site-packages/selenium/webdriver/remote/errorhandler.py", line 242, in check_response
    raise exception_class(message, screen, stacktrace)
selenium.common.exceptions.NoSuchElementException: Message: Unable to locate element: //div[@class="infoEntity"]//label[text()="Competitors"]//following-sibling::*

2020-07-20 18:28:04 - root - INFO - Insert company to DB successfully
2020-07-20 18:28:04 - root - INFO - Insert job to DB successfully
2020-07-20 18:28:31 - root - INFO - Insert company to DB successfully
2020-07-20 18:28:31 - root - INFO - Get information from DB
2020-07-20 18:28:31 - root - INFO - Insert competitors to DB successfully
2020-07-20 18:28:31 - root - INFO - Get information from DB
2020-07-20 18:28:31 - root - INFO - Insert competitors to DB successfully
2020-07-20 18:28:31 - root - INFO - Get information from DB
2020-07-20 18:28:31 - root - INFO - Insert competitors to DB successfully
2020-07-20 18:28:31 - root - INFO - Insert job to DB successfully
2020-07-20 18:28:58 - root - INFO - Insert company to DB successfully
2020-07-20 18:28:58 - root - INFO - Get information from DB
2020-07-20 18:29:08 - root - INFO - Browser connect to URL
2020-07-20 18:29:12 - root - INFO - Search for competitor's company page
2020-07-20 18:29:12 - root - ERROR - No popup to close
Traceback (most recent call last):
  File "/Users/Sheryl/PycharmProjects/Itc_data_mining/scraper.py", line 28, in close_popup
    """
  File "/Users/Sheryl/PycharmProjects/Itc_data_mining/data_mining/lib/python3.6/site-packages/selenium/webdriver/remote/webdriver.py", line 394, in find_element_by_xpath
    return self.find_element(by=By.XPATH, value=xpath)
  File "/Users/Sheryl/PycharmProjects/Itc_data_mining/data_mining/lib/python3.6/site-packages/selenium/webdriver/remote/webdriver.py", line 978, in find_element
    'value': value})['value']
  File "/Users/Sheryl/PycharmProjects/Itc_data_mining/data_mining/lib/python3.6/site-packages/selenium/webdriver/remote/webdriver.py", line 321, in execute
    self.error_handler.check_response(response)
  File "/Users/Sheryl/PycharmProjects/Itc_data_mining/data_mining/lib/python3.6/site-packages/selenium/webdriver/remote/errorhandler.py", line 242, in check_response
    raise exception_class(message, screen, stacktrace)
selenium.common.exceptions.NoSuchElementException: Message: Unable to locate element: //div[contains(@class,'modal_main')]//span[@class='SVGInline modal_closeIcon']

2020-07-20 18:29:19 - root - INFO - Browser connect to new URL of a company
2020-07-20 18:29:46 - root - INFO - Close browser successfully
2020-07-20 18:29:46 - root - INFO - Insert company to DB successfully
2020-07-20 18:29:46 - root - INFO - Insert competitors to DB successfully
2020-07-20 18:29:46 - root - INFO - Get information from DB
2020-07-20 18:29:55 - root - INFO - Browser connect to URL
2020-07-20 18:29:57 - root - INFO - Search for competitor's company page
2020-07-20 18:29:57 - root - ERROR - No popup to close
Traceback (most recent call last):
  File "/Users/Sheryl/PycharmProjects/Itc_data_mining/scraper.py", line 28, in close_popup
    # Close pop up
  File "/Users/Sheryl/PycharmProjects/Itc_data_mining/data_mining/lib/python3.6/site-packages/selenium/webdriver/remote/webdriver.py", line 394, in find_element_by_xpath
    return self.find_element(by=By.XPATH, value=xpath)
  File "/Users/Sheryl/PycharmProjects/Itc_data_mining/data_mining/lib/python3.6/site-packages/selenium/webdriver/remote/webdriver.py", line 978, in find_element
    'value': value})['value']
  File "/Users/Sheryl/PycharmProjects/Itc_data_mining/data_mining/lib/python3.6/site-packages/selenium/webdriver/remote/webdriver.py", line 321, in execute
    self.error_handler.check_response(response)
  File "/Users/Sheryl/PycharmProjects/Itc_data_mining/data_mining/lib/python3.6/site-packages/selenium/webdriver/remote/errorhandler.py", line 242, in check_response
    raise exception_class(message, screen, stacktrace)
selenium.common.exceptions.NoSuchElementException: Message: Unable to locate element: //div[contains(@class,'modal_main')]//span[@class='SVGInline modal_closeIcon']

2020-07-20 18:30:03 - root - INFO - Browser connect to new URL of a company
2020-07-20 18:30:34 - root - INFO - Close browser successfully
2020-07-20 18:30:34 - root - INFO - Insert company to DB successfully
2020-07-20 18:30:34 - root - INFO - Insert competitors to DB successfully
2020-07-20 18:30:34 - root - INFO - Get information from DB
2020-07-20 18:30:43 - root - INFO - Browser connect to URL
2020-07-20 18:30:46 - root - INFO - Search for competitor's company page
2020-07-20 18:30:46 - root - ERROR - No popup to close
Traceback (most recent call last):
  File "/Users/Sheryl/PycharmProjects/Itc_data_mining/scraper.py", line 28, in close_popup
    # Close pop up
  File "/Users/Sheryl/PycharmProjects/Itc_data_mining/data_mining/lib/python3.6/site-packages/selenium/webdriver/remote/webdriver.py", line 394, in find_element_by_xpath
    return self.find_element(by=By.XPATH, value=xpath)
  File "/Users/Sheryl/PycharmProjects/Itc_data_mining/data_mining/lib/python3.6/site-packages/selenium/webdriver/remote/webdriver.py", line 978, in find_element
    'value': value})['value']
  File "/Users/Sheryl/PycharmProjects/Itc_data_mining/data_mining/lib/python3.6/site-packages/selenium/webdriver/remote/webdriver.py", line 321, in execute
    self.error_handler.check_response(response)
  File "/Users/Sheryl/PycharmProjects/Itc_data_mining/data_mining/lib/python3.6/site-packages/selenium/webdriver/remote/errorhandler.py", line 242, in check_response
    raise exception_class(message, screen, stacktrace)
selenium.common.exceptions.NoSuchElementException: Message: Unable to locate element: //div[contains(@class,'modal_main')]//span[@class='SVGInline modal_closeIcon']

2020-07-20 18:30:52 - root - INFO - Browser connect to new URL of a company
2020-07-20 18:31:19 - root - INFO - Close browser successfully
2020-07-20 18:31:19 - root - INFO - Insert company to DB successfully
2020-07-20 18:31:19 - root - INFO - Insert competitors to DB successfully
2020-07-20 18:31:19 - root - INFO - Insert job to DB successfully
2020-07-20 18:31:45 - root - ERROR - There is a problem with catching text from xpath
Traceback (most recent call last):
  File "/Users/Sheryl/PycharmProjects/Itc_data_mining/scraper.py", line 42, in catch_optional_text_value_by_xpath
    try:
  File "/Users/Sheryl/PycharmProjects/Itc_data_mining/data_mining/lib/python3.6/site-packages/selenium/webdriver/remote/webdriver.py", line 394, in find_element_by_xpath
    return self.find_element(by=By.XPATH, value=xpath)
  File "/Users/Sheryl/PycharmProjects/Itc_data_mining/data_mining/lib/python3.6/site-packages/selenium/webdriver/remote/webdriver.py", line 978, in find_element
    'value': value})['value']
  File "/Users/Sheryl/PycharmProjects/Itc_data_mining/data_mining/lib/python3.6/site-packages/selenium/webdriver/remote/webdriver.py", line 321, in execute
    self.error_handler.check_response(response)
  File "/Users/Sheryl/PycharmProjects/Itc_data_mining/data_mining/lib/python3.6/site-packages/selenium/webdriver/remote/errorhandler.py", line 242, in check_response
    raise exception_class(message, screen, stacktrace)
selenium.common.exceptions.NoSuchElementException: Message: Unable to locate element: //div[@class="infoEntity"]//label[text()="Competitors"]//following-sibling::*

2020-07-20 18:31:45 - root - INFO - Insert company to DB successfully
2020-07-20 18:31:45 - root - INFO - Insert job to DB successfully
2020-07-20 18:32:11 - root - ERROR - There is a problem with catching text from xpath
Traceback (most recent call last):
  File "/Users/Sheryl/PycharmProjects/Itc_data_mining/scraper.py", line 42, in catch_optional_text_value_by_xpath
    try:
  File "/Users/Sheryl/PycharmProjects/Itc_data_mining/data_mining/lib/python3.6/site-packages/selenium/webdriver/remote/webdriver.py", line 394, in find_element_by_xpath
    return self.find_element(by=By.XPATH, value=xpath)
  File "/Users/Sheryl/PycharmProjects/Itc_data_mining/data_mining/lib/python3.6/site-packages/selenium/webdriver/remote/webdriver.py", line 978, in find_element
    'value': value})['value']
  File "/Users/Sheryl/PycharmProjects/Itc_data_mining/data_mining/lib/python3.6/site-packages/selenium/webdriver/remote/webdriver.py", line 321, in execute
    self.error_handler.check_response(response)
  File "/Users/Sheryl/PycharmProjects/Itc_data_mining/data_mining/lib/python3.6/site-packages/selenium/webdriver/remote/errorhandler.py", line 242, in check_response
    raise exception_class(message, screen, stacktrace)
selenium.common.exceptions.NoSuchElementException: Message: Unable to locate element: //div[@class="infoEntity"]//label[text()="Competitors"]//following-sibling::*

2020-07-20 18:32:11 - root - INFO - Insert company to DB successfully
2020-07-20 18:32:11 - root - INFO - Insert job to DB successfully
2020-07-20 18:32:38 - root - ERROR - There is a problem with catching text from xpath
Traceback (most recent call last):
  File "/Users/Sheryl/PycharmProjects/Itc_data_mining/scraper.py", line 42, in catch_optional_text_value_by_xpath
    try:
  File "/Users/Sheryl/PycharmProjects/Itc_data_mining/data_mining/lib/python3.6/site-packages/selenium/webdriver/remote/webdriver.py", line 394, in find_element_by_xpath
    return self.find_element(by=By.XPATH, value=xpath)
  File "/Users/Sheryl/PycharmProjects/Itc_data_mining/data_mining/lib/python3.6/site-packages/selenium/webdriver/remote/webdriver.py", line 978, in find_element
    'value': value})['value']
  File "/Users/Sheryl/PycharmProjects/Itc_data_mining/data_mining/lib/python3.6/site-packages/selenium/webdriver/remote/webdriver.py", line 321, in execute
    self.error_handler.check_response(response)
  File "/Users/Sheryl/PycharmProjects/Itc_data_mining/data_mining/lib/python3.6/site-packages/selenium/webdriver/remote/errorhandler.py", line 242, in check_response
    raise exception_class(message, screen, stacktrace)
selenium.common.exceptions.NoSuchElementException: Message: Unable to locate element: //div[@class="infoEntity"]//label[text()="Founded"]//following-sibling::*

2020-07-20 18:32:38 - root - ERROR - There is a problem with catching text from xpath
Traceback (most recent call last):
  File "/Users/Sheryl/PycharmProjects/Itc_data_mining/scraper.py", line 42, in catch_optional_text_value_by_xpath
    try:
  File "/Users/Sheryl/PycharmProjects/Itc_data_mining/data_mining/lib/python3.6/site-packages/selenium/webdriver/remote/webdriver.py", line 394, in find_element_by_xpath
    return self.find_element(by=By.XPATH, value=xpath)
  File "/Users/Sheryl/PycharmProjects/Itc_data_mining/data_mining/lib/python3.6/site-packages/selenium/webdriver/remote/webdriver.py", line 978, in find_element
    'value': value})['value']
  File "/Users/Sheryl/PycharmProjects/Itc_data_mining/data_mining/lib/python3.6/site-packages/selenium/webdriver/remote/webdriver.py", line 321, in execute
    self.error_handler.check_response(response)
  File "/Users/Sheryl/PycharmProjects/Itc_data_mining/data_mining/lib/python3.6/site-packages/selenium/webdriver/remote/errorhandler.py", line 242, in check_response
    raise exception_class(message, screen, stacktrace)
selenium.common.exceptions.NoSuchElementException: Message: Unable to locate element: //div[@class="infoEntity"]//label[text()="Industry"]//following-sibling::*

2020-07-20 18:32:38 - root - ERROR - There is a problem with catching text from xpath
Traceback (most recent call last):
  File "/Users/Sheryl/PycharmProjects/Itc_data_mining/scraper.py", line 42, in catch_optional_text_value_by_xpath
    try:
  File "/Users/Sheryl/PycharmProjects/Itc_data_mining/data_mining/lib/python3.6/site-packages/selenium/webdriver/remote/webdriver.py", line 394, in find_element_by_xpath
    return self.find_element(by=By.XPATH, value=xpath)
  File "/Users/Sheryl/PycharmProjects/Itc_data_mining/data_mining/lib/python3.6/site-packages/selenium/webdriver/remote/webdriver.py", line 978, in find_element
    'value': value})['value']
  File "/Users/Sheryl/PycharmProjects/Itc_data_mining/data_mining/lib/python3.6/site-packages/selenium/webdriver/remote/webdriver.py", line 321, in execute
    self.error_handler.check_response(response)
  File "/Users/Sheryl/PycharmProjects/Itc_data_mining/data_mining/lib/python3.6/site-packages/selenium/webdriver/remote/errorhandler.py", line 242, in check_response
    raise exception_class(message, screen, stacktrace)
selenium.common.exceptions.NoSuchElementException: Message: Unable to locate element: //div[@class="infoEntity"]//label[text()="Sector"]//following-sibling::*

2020-07-20 18:32:38 - root - ERROR - There is a problem with catching text from xpath
Traceback (most recent call last):
  File "/Users/Sheryl/PycharmProjects/Itc_data_mining/scraper.py", line 42, in catch_optional_text_value_by_xpath
    try:
  File "/Users/Sheryl/PycharmProjects/Itc_data_mining/data_mining/lib/python3.6/site-packages/selenium/webdriver/remote/webdriver.py", line 394, in find_element_by_xpath
    return self.find_element(by=By.XPATH, value=xpath)
  File "/Users/Sheryl/PycharmProjects/Itc_data_mining/data_mining/lib/python3.6/site-packages/selenium/webdriver/remote/webdriver.py", line 978, in find_element
    'value': value})['value']
  File "/Users/Sheryl/PycharmProjects/Itc_data_mining/data_mining/lib/python3.6/site-packages/selenium/webdriver/remote/webdriver.py", line 321, in execute
    self.error_handler.check_response(response)
  File "/Users/Sheryl/PycharmProjects/Itc_data_mining/data_mining/lib/python3.6/site-packages/selenium/webdriver/remote/errorhandler.py", line 242, in check_response
    raise exception_class(message, screen, stacktrace)
selenium.common.exceptions.NoSuchElementException: Message: Unable to locate element: //div[@class="infoEntity"]//label[text()="Competitors"]//following-sibling::*

2020-07-20 18:32:38 - root - INFO - Insert company to DB successfully
2020-07-20 18:32:38 - root - INFO - Insert job to DB successfully
2020-07-20 18:33:05 - root - INFO - Insert company to DB successfully
2020-07-20 18:33:05 - root - INFO - Get information from DB
2020-07-20 18:33:05 - root - INFO - Insert competitors to DB successfully
2020-07-20 18:33:05 - root - INFO - Get information from DB
2020-07-20 18:33:05 - root - INFO - Insert competitors to DB successfully
2020-07-20 18:33:05 - root - INFO - Get information from DB
2020-07-20 18:33:05 - root - INFO - Insert competitors to DB successfully
2020-07-20 18:33:05 - root - INFO - Insert job to DB successfully
2020-07-20 18:33:32 - root - ERROR - There is a problem with catching text from xpath
Traceback (most recent call last):
  File "/Users/Sheryl/PycharmProjects/Itc_data_mining/scraper.py", line 42, in catch_optional_text_value_by_xpath
    try:
  File "/Users/Sheryl/PycharmProjects/Itc_data_mining/data_mining/lib/python3.6/site-packages/selenium/webdriver/remote/webdriver.py", line 394, in find_element_by_xpath
    return self.find_element(by=By.XPATH, value=xpath)
  File "/Users/Sheryl/PycharmProjects/Itc_data_mining/data_mining/lib/python3.6/site-packages/selenium/webdriver/remote/webdriver.py", line 978, in find_element
    'value': value})['value']
  File "/Users/Sheryl/PycharmProjects/Itc_data_mining/data_mining/lib/python3.6/site-packages/selenium/webdriver/remote/webdriver.py", line 321, in execute
    self.error_handler.check_response(response)
  File "/Users/Sheryl/PycharmProjects/Itc_data_mining/data_mining/lib/python3.6/site-packages/selenium/webdriver/remote/errorhandler.py", line 242, in check_response
    raise exception_class(message, screen, stacktrace)
selenium.common.exceptions.NoSuchElementException: Message: Unable to locate element: //div[@class="infoEntity"]//label[text()="Founded"]//following-sibling::*

2020-07-20 18:33:32 - root - ERROR - There is a problem with catching text from xpath
Traceback (most recent call last):
  File "/Users/Sheryl/PycharmProjects/Itc_data_mining/scraper.py", line 42, in catch_optional_text_value_by_xpath
    try:
  File "/Users/Sheryl/PycharmProjects/Itc_data_mining/data_mining/lib/python3.6/site-packages/selenium/webdriver/remote/webdriver.py", line 394, in find_element_by_xpath
    return self.find_element(by=By.XPATH, value=xpath)
  File "/Users/Sheryl/PycharmProjects/Itc_data_mining/data_mining/lib/python3.6/site-packages/selenium/webdriver/remote/webdriver.py", line 978, in find_element
    'value': value})['value']
  File "/Users/Sheryl/PycharmProjects/Itc_data_mining/data_mining/lib/python3.6/site-packages/selenium/webdriver/remote/webdriver.py", line 321, in execute
    self.error_handler.check_response(response)
  File "/Users/Sheryl/PycharmProjects/Itc_data_mining/data_mining/lib/python3.6/site-packages/selenium/webdriver/remote/errorhandler.py", line 242, in check_response
    raise exception_class(message, screen, stacktrace)
selenium.common.exceptions.NoSuchElementException: Message: Unable to locate element: //div[@class="infoEntity"]//label[text()="Industry"]//following-sibling::*

2020-07-20 18:33:32 - root - ERROR - There is a problem with catching text from xpath
Traceback (most recent call last):
  File "/Users/Sheryl/PycharmProjects/Itc_data_mining/scraper.py", line 42, in catch_optional_text_value_by_xpath
    try:
  File "/Users/Sheryl/PycharmProjects/Itc_data_mining/data_mining/lib/python3.6/site-packages/selenium/webdriver/remote/webdriver.py", line 394, in find_element_by_xpath
    return self.find_element(by=By.XPATH, value=xpath)
  File "/Users/Sheryl/PycharmProjects/Itc_data_mining/data_mining/lib/python3.6/site-packages/selenium/webdriver/remote/webdriver.py", line 978, in find_element
    'value': value})['value']
  File "/Users/Sheryl/PycharmProjects/Itc_data_mining/data_mining/lib/python3.6/site-packages/selenium/webdriver/remote/webdriver.py", line 321, in execute
    self.error_handler.check_response(response)
  File "/Users/Sheryl/PycharmProjects/Itc_data_mining/data_mining/lib/python3.6/site-packages/selenium/webdriver/remote/errorhandler.py", line 242, in check_response
    raise exception_class(message, screen, stacktrace)
selenium.common.exceptions.NoSuchElementException: Message: Unable to locate element: //div[@class="infoEntity"]//label[text()="Sector"]//following-sibling::*

2020-07-20 18:33:32 - root - ERROR - There is a problem with catching text from xpath
Traceback (most recent call last):
  File "/Users/Sheryl/PycharmProjects/Itc_data_mining/scraper.py", line 42, in catch_optional_text_value_by_xpath
    try:
  File "/Users/Sheryl/PycharmProjects/Itc_data_mining/data_mining/lib/python3.6/site-packages/selenium/webdriver/remote/webdriver.py", line 394, in find_element_by_xpath
    return self.find_element(by=By.XPATH, value=xpath)
  File "/Users/Sheryl/PycharmProjects/Itc_data_mining/data_mining/lib/python3.6/site-packages/selenium/webdriver/remote/webdriver.py", line 978, in find_element
    'value': value})['value']
  File "/Users/Sheryl/PycharmProjects/Itc_data_mining/data_mining/lib/python3.6/site-packages/selenium/webdriver/remote/webdriver.py", line 321, in execute
    self.error_handler.check_response(response)
  File "/Users/Sheryl/PycharmProjects/Itc_data_mining/data_mining/lib/python3.6/site-packages/selenium/webdriver/remote/errorhandler.py", line 242, in check_response
    raise exception_class(message, screen, stacktrace)
selenium.common.exceptions.NoSuchElementException: Message: Unable to locate element: //div[@class="infoEntity"]//label[text()="Competitors"]//following-sibling::*

2020-07-20 18:33:32 - root - INFO - Insert company to DB successfully
2020-07-20 18:33:32 - root - INFO - Insert job to DB successfully
