2020-07-20 17:09:11 - root - INFO - Connection with MYSQL ready
2020-07-20 17:09:11 - root - INFO - Database was created successfully
2020-07-20 17:09:12 - root - INFO - Tables were created successfully
2020-07-20 17:09:35 - root - INFO - Browser connect to URL
2020-07-20 17:09:35 - root - INFO - Search for job title
2020-07-20 17:09:35 - root - INFO - Search for job location
2020-07-20 17:09:44 - root - ERROR - No popup to close
Traceback (most recent call last):
  File "/Users/Sheryl/PycharmProjects/Itc_data_mining/scraper.py", line 28, in close_popup
    pop_up = self.browser.find_element_by_xpath(cst.POP_UP_XPATH)
  File "/Users/Sheryl/PycharmProjects/Itc_data_mining/data_mining/lib/python3.6/site-packages/selenium/webdriver/remote/webdriver.py", line 394, in find_element_by_xpath
    return self.find_element(by=By.XPATH, value=xpath)
  File "/Users/Sheryl/PycharmProjects/Itc_data_mining/data_mining/lib/python3.6/site-packages/selenium/webdriver/remote/webdriver.py", line 978, in find_element
    'value': value})['value']
  File "/Users/Sheryl/PycharmProjects/Itc_data_mining/data_mining/lib/python3.6/site-packages/selenium/webdriver/remote/webdriver.py", line 321, in execute
    self.error_handler.check_response(response)
  File "/Users/Sheryl/PycharmProjects/Itc_data_mining/data_mining/lib/python3.6/site-packages/selenium/webdriver/remote/errorhandler.py", line 242, in check_response
    raise exception_class(message, screen, stacktrace)
selenium.common.exceptions.NoSuchElementException: Message: Unable to locate element: //div[contains(@class,'modal_main')]//span[@class='SVGInline modal_closeIcon']

2020-07-20 17:09:51 - root - INFO - Browser connect to new URL
2020-07-20 17:10:09 - root - ERROR - No popup to close
Traceback (most recent call last):
  File "/Users/Sheryl/PycharmProjects/Itc_data_mining/scraper.py", line 28, in close_popup
    pop_up = self.browser.find_element_by_xpath(cst.POP_UP_XPATH)
  File "/Users/Sheryl/PycharmProjects/Itc_data_mining/data_mining/lib/python3.6/site-packages/selenium/webdriver/remote/webdriver.py", line 394, in find_element_by_xpath
    return self.find_element(by=By.XPATH, value=xpath)
  File "/Users/Sheryl/PycharmProjects/Itc_data_mining/data_mining/lib/python3.6/site-packages/selenium/webdriver/remote/webdriver.py", line 978, in find_element
    'value': value})['value']
  File "/Users/Sheryl/PycharmProjects/Itc_data_mining/data_mining/lib/python3.6/site-packages/selenium/webdriver/remote/webdriver.py", line 321, in execute
    self.error_handler.check_response(response)
  File "/Users/Sheryl/PycharmProjects/Itc_data_mining/data_mining/lib/python3.6/site-packages/selenium/webdriver/remote/errorhandler.py", line 242, in check_response
    raise exception_class(message, screen, stacktrace)
selenium.common.exceptions.NoSuchElementException: Message: Unable to locate element: //div[contains(@class,'modal_main')]//span[@class='SVGInline modal_closeIcon']

2020-07-20 17:10:09 - root - INFO - Succeed to catch number of available pages
2020-07-20 17:10:20 - root - INFO - Succeed to close popup
2020-07-20 17:10:20 - root - INFO - Start to collect all data from page
2020-07-20 17:10:50 - root - ERROR - There is a problem with catching text from xpath
Traceback (most recent call last):
  File "/Users/Sheryl/PycharmProjects/Itc_data_mining/scraper.py", line 42, in catch_optional_text_value_by_xpath
    text_value = self.browser.find_element_by_xpath(x_path).text
  File "/Users/Sheryl/PycharmProjects/Itc_data_mining/data_mining/lib/python3.6/site-packages/selenium/webdriver/remote/webdriver.py", line 394, in find_element_by_xpath
    return self.find_element(by=By.XPATH, value=xpath)
  File "/Users/Sheryl/PycharmProjects/Itc_data_mining/data_mining/lib/python3.6/site-packages/selenium/webdriver/remote/webdriver.py", line 978, in find_element
    'value': value})['value']
  File "/Users/Sheryl/PycharmProjects/Itc_data_mining/data_mining/lib/python3.6/site-packages/selenium/webdriver/remote/webdriver.py", line 321, in execute
    self.error_handler.check_response(response)
  File "/Users/Sheryl/PycharmProjects/Itc_data_mining/data_mining/lib/python3.6/site-packages/selenium/webdriver/remote/errorhandler.py", line 242, in check_response
    raise exception_class(message, screen, stacktrace)
selenium.common.exceptions.NoSuchElementException: Message: Unable to locate element: //div[@class="infoEntity"]//label[text()="Competitors"]//following-sibling::*

2020-07-20 17:10:50 - root - INFO - Insert company to DB successfully
2020-07-20 17:10:50 - root - INFO - Insert job to DB successfully
2020-07-20 17:11:20 - root - INFO - Insert company to DB successfully
2020-07-20 17:11:20 - root - INFO - Get information from DB
2020-07-20 17:11:20 - root - INFO - Insert competitors to DB successfully
2020-07-20 17:11:20 - root - INFO - Get information from DB
2020-07-20 17:11:20 - root - INFO - Insert competitors to DB successfully
2020-07-20 17:11:20 - root - INFO - Get information from DB
2020-07-20 17:11:20 - root - INFO - Insert competitors to DB successfully
2020-07-20 17:11:20 - root - INFO - Insert job to DB successfully
2020-07-20 17:11:50 - root - ERROR - There is a problem with catching text from xpath
Traceback (most recent call last):
  File "/Users/Sheryl/PycharmProjects/Itc_data_mining/scraper.py", line 42, in catch_optional_text_value_by_xpath
    text_value = self.browser.find_element_by_xpath(x_path).text
  File "/Users/Sheryl/PycharmProjects/Itc_data_mining/data_mining/lib/python3.6/site-packages/selenium/webdriver/remote/webdriver.py", line 394, in find_element_by_xpath
    return self.find_element(by=By.XPATH, value=xpath)
  File "/Users/Sheryl/PycharmProjects/Itc_data_mining/data_mining/lib/python3.6/site-packages/selenium/webdriver/remote/webdriver.py", line 978, in find_element
    'value': value})['value']
  File "/Users/Sheryl/PycharmProjects/Itc_data_mining/data_mining/lib/python3.6/site-packages/selenium/webdriver/remote/webdriver.py", line 321, in execute
    self.error_handler.check_response(response)
  File "/Users/Sheryl/PycharmProjects/Itc_data_mining/data_mining/lib/python3.6/site-packages/selenium/webdriver/remote/errorhandler.py", line 242, in check_response
    raise exception_class(message, screen, stacktrace)
selenium.common.exceptions.NoSuchElementException: Message: Unable to locate element: //div[@class="infoEntity"]//label[text()="Competitors"]//following-sibling::*

2020-07-20 17:11:50 - root - INFO - Insert company to DB successfully
2020-07-20 17:11:50 - root - INFO - Insert job to DB successfully
2020-07-20 17:12:18 - root - ERROR - There is a problem with catching text from xpath
Traceback (most recent call last):
  File "/Users/Sheryl/PycharmProjects/Itc_data_mining/scraper.py", line 42, in catch_optional_text_value_by_xpath
    text_value = self.browser.find_element_by_xpath(x_path).text
  File "/Users/Sheryl/PycharmProjects/Itc_data_mining/data_mining/lib/python3.6/site-packages/selenium/webdriver/remote/webdriver.py", line 394, in find_element_by_xpath
    return self.find_element(by=By.XPATH, value=xpath)
  File "/Users/Sheryl/PycharmProjects/Itc_data_mining/data_mining/lib/python3.6/site-packages/selenium/webdriver/remote/webdriver.py", line 978, in find_element
    'value': value})['value']
  File "/Users/Sheryl/PycharmProjects/Itc_data_mining/data_mining/lib/python3.6/site-packages/selenium/webdriver/remote/webdriver.py", line 321, in execute
    self.error_handler.check_response(response)
  File "/Users/Sheryl/PycharmProjects/Itc_data_mining/data_mining/lib/python3.6/site-packages/selenium/webdriver/remote/errorhandler.py", line 242, in check_response
    raise exception_class(message, screen, stacktrace)
selenium.common.exceptions.NoSuchElementException: Message: Unable to locate element: //div[@class="infoEntity"]//label[text()="Size"]//following-sibling::*

2020-07-20 17:12:18 - root - ERROR - There is a problem with catching text from xpath
Traceback (most recent call last):
  File "/Users/Sheryl/PycharmProjects/Itc_data_mining/scraper.py", line 42, in catch_optional_text_value_by_xpath
    text_value = self.browser.find_element_by_xpath(x_path).text
  File "/Users/Sheryl/PycharmProjects/Itc_data_mining/data_mining/lib/python3.6/site-packages/selenium/webdriver/remote/webdriver.py", line 394, in find_element_by_xpath
    return self.find_element(by=By.XPATH, value=xpath)
  File "/Users/Sheryl/PycharmProjects/Itc_data_mining/data_mining/lib/python3.6/site-packages/selenium/webdriver/remote/webdriver.py", line 978, in find_element
    'value': value})['value']
  File "/Users/Sheryl/PycharmProjects/Itc_data_mining/data_mining/lib/python3.6/site-packages/selenium/webdriver/remote/webdriver.py", line 321, in execute
    self.error_handler.check_response(response)
  File "/Users/Sheryl/PycharmProjects/Itc_data_mining/data_mining/lib/python3.6/site-packages/selenium/webdriver/remote/errorhandler.py", line 242, in check_response
    raise exception_class(message, screen, stacktrace)
selenium.common.exceptions.NoSuchElementException: Message: Unable to locate element: //div[@class="infoEntity"]//label[text()="Founded"]//following-sibling::*

2020-07-20 17:12:18 - root - ERROR - There is a problem with catching text from xpath
Traceback (most recent call last):
  File "/Users/Sheryl/PycharmProjects/Itc_data_mining/scraper.py", line 42, in catch_optional_text_value_by_xpath
    text_value = self.browser.find_element_by_xpath(x_path).text
  File "/Users/Sheryl/PycharmProjects/Itc_data_mining/data_mining/lib/python3.6/site-packages/selenium/webdriver/remote/webdriver.py", line 394, in find_element_by_xpath
    return self.find_element(by=By.XPATH, value=xpath)
  File "/Users/Sheryl/PycharmProjects/Itc_data_mining/data_mining/lib/python3.6/site-packages/selenium/webdriver/remote/webdriver.py", line 978, in find_element
    'value': value})['value']
  File "/Users/Sheryl/PycharmProjects/Itc_data_mining/data_mining/lib/python3.6/site-packages/selenium/webdriver/remote/webdriver.py", line 321, in execute
    self.error_handler.check_response(response)
  File "/Users/Sheryl/PycharmProjects/Itc_data_mining/data_mining/lib/python3.6/site-packages/selenium/webdriver/remote/errorhandler.py", line 242, in check_response
    raise exception_class(message, screen, stacktrace)
selenium.common.exceptions.NoSuchElementException: Message: Unable to locate element: //div[@class="infoEntity"]//label[text()="Industry"]//following-sibling::*

2020-07-20 17:12:18 - root - ERROR - There is a problem with catching text from xpath
Traceback (most recent call last):
  File "/Users/Sheryl/PycharmProjects/Itc_data_mining/scraper.py", line 42, in catch_optional_text_value_by_xpath
    text_value = self.browser.find_element_by_xpath(x_path).text
  File "/Users/Sheryl/PycharmProjects/Itc_data_mining/data_mining/lib/python3.6/site-packages/selenium/webdriver/remote/webdriver.py", line 394, in find_element_by_xpath
    return self.find_element(by=By.XPATH, value=xpath)
  File "/Users/Sheryl/PycharmProjects/Itc_data_mining/data_mining/lib/python3.6/site-packages/selenium/webdriver/remote/webdriver.py", line 978, in find_element
    'value': value})['value']
  File "/Users/Sheryl/PycharmProjects/Itc_data_mining/data_mining/lib/python3.6/site-packages/selenium/webdriver/remote/webdriver.py", line 321, in execute
    self.error_handler.check_response(response)
  File "/Users/Sheryl/PycharmProjects/Itc_data_mining/data_mining/lib/python3.6/site-packages/selenium/webdriver/remote/errorhandler.py", line 242, in check_response
    raise exception_class(message, screen, stacktrace)
selenium.common.exceptions.NoSuchElementException: Message: Unable to locate element: //div[@class="infoEntity"]//label[text()="Sector"]//following-sibling::*

2020-07-20 17:12:18 - root - ERROR - There is a problem with catching text from xpath
Traceback (most recent call last):
  File "/Users/Sheryl/PycharmProjects/Itc_data_mining/scraper.py", line 42, in catch_optional_text_value_by_xpath
    text_value = self.browser.find_element_by_xpath(x_path).text
  File "/Users/Sheryl/PycharmProjects/Itc_data_mining/data_mining/lib/python3.6/site-packages/selenium/webdriver/remote/webdriver.py", line 394, in find_element_by_xpath
    return self.find_element(by=By.XPATH, value=xpath)
  File "/Users/Sheryl/PycharmProjects/Itc_data_mining/data_mining/lib/python3.6/site-packages/selenium/webdriver/remote/webdriver.py", line 978, in find_element
    'value': value})['value']
  File "/Users/Sheryl/PycharmProjects/Itc_data_mining/data_mining/lib/python3.6/site-packages/selenium/webdriver/remote/webdriver.py", line 321, in execute
    self.error_handler.check_response(response)
  File "/Users/Sheryl/PycharmProjects/Itc_data_mining/data_mining/lib/python3.6/site-packages/selenium/webdriver/remote/errorhandler.py", line 242, in check_response
    raise exception_class(message, screen, stacktrace)
selenium.common.exceptions.NoSuchElementException: Message: Unable to locate element: //div[@class="infoEntity"]//label[text()="Type"]//following-sibling::*

2020-07-20 17:12:18 - root - ERROR - There is a problem with catching text from xpath
Traceback (most recent call last):
  File "/Users/Sheryl/PycharmProjects/Itc_data_mining/scraper.py", line 42, in catch_optional_text_value_by_xpath
    text_value = self.browser.find_element_by_xpath(x_path).text
  File "/Users/Sheryl/PycharmProjects/Itc_data_mining/data_mining/lib/python3.6/site-packages/selenium/webdriver/remote/webdriver.py", line 394, in find_element_by_xpath
    return self.find_element(by=By.XPATH, value=xpath)
  File "/Users/Sheryl/PycharmProjects/Itc_data_mining/data_mining/lib/python3.6/site-packages/selenium/webdriver/remote/webdriver.py", line 978, in find_element
    'value': value})['value']
  File "/Users/Sheryl/PycharmProjects/Itc_data_mining/data_mining/lib/python3.6/site-packages/selenium/webdriver/remote/webdriver.py", line 321, in execute
    self.error_handler.check_response(response)
  File "/Users/Sheryl/PycharmProjects/Itc_data_mining/data_mining/lib/python3.6/site-packages/selenium/webdriver/remote/errorhandler.py", line 242, in check_response
    raise exception_class(message, screen, stacktrace)
selenium.common.exceptions.NoSuchElementException: Message: Unable to locate element: //div[@class="infoEntity"]//label[text()="Revenue"]//following-sibling::*

2020-07-20 17:12:18 - root - ERROR - There is a problem with catching text from xpath
Traceback (most recent call last):
  File "/Users/Sheryl/PycharmProjects/Itc_data_mining/scraper.py", line 42, in catch_optional_text_value_by_xpath
    text_value = self.browser.find_element_by_xpath(x_path).text
  File "/Users/Sheryl/PycharmProjects/Itc_data_mining/data_mining/lib/python3.6/site-packages/selenium/webdriver/remote/webdriver.py", line 394, in find_element_by_xpath
    return self.find_element(by=By.XPATH, value=xpath)
  File "/Users/Sheryl/PycharmProjects/Itc_data_mining/data_mining/lib/python3.6/site-packages/selenium/webdriver/remote/webdriver.py", line 978, in find_element
    'value': value})['value']
  File "/Users/Sheryl/PycharmProjects/Itc_data_mining/data_mining/lib/python3.6/site-packages/selenium/webdriver/remote/webdriver.py", line 321, in execute
    self.error_handler.check_response(response)
  File "/Users/Sheryl/PycharmProjects/Itc_data_mining/data_mining/lib/python3.6/site-packages/selenium/webdriver/remote/errorhandler.py", line 242, in check_response
    raise exception_class(message, screen, stacktrace)
selenium.common.exceptions.NoSuchElementException: Message: Unable to locate element: //div[@class="infoEntity"]//label[text()="Headquarters"]//following-sibling::*

2020-07-20 17:12:18 - root - ERROR - There is a problem with catching text from xpath
Traceback (most recent call last):
  File "/Users/Sheryl/PycharmProjects/Itc_data_mining/scraper.py", line 42, in catch_optional_text_value_by_xpath
    text_value = self.browser.find_element_by_xpath(x_path).text
  File "/Users/Sheryl/PycharmProjects/Itc_data_mining/data_mining/lib/python3.6/site-packages/selenium/webdriver/remote/webdriver.py", line 394, in find_element_by_xpath
    return self.find_element(by=By.XPATH, value=xpath)
  File "/Users/Sheryl/PycharmProjects/Itc_data_mining/data_mining/lib/python3.6/site-packages/selenium/webdriver/remote/webdriver.py", line 978, in find_element
    'value': value})['value']
  File "/Users/Sheryl/PycharmProjects/Itc_data_mining/data_mining/lib/python3.6/site-packages/selenium/webdriver/remote/webdriver.py", line 321, in execute
    self.error_handler.check_response(response)
  File "/Users/Sheryl/PycharmProjects/Itc_data_mining/data_mining/lib/python3.6/site-packages/selenium/webdriver/remote/errorhandler.py", line 242, in check_response
    raise exception_class(message, screen, stacktrace)
selenium.common.exceptions.NoSuchElementException: Message: Unable to locate element: //div[@class="infoEntity"]//label[text()="Competitors"]//following-sibling::*

2020-07-20 17:12:18 - root - INFO - Insert company to DB successfully
2020-07-20 17:12:18 - root - INFO - Insert job to DB successfully
2020-07-20 17:12:48 - root - ERROR - There is a problem with catching text from xpath
Traceback (most recent call last):
  File "/Users/Sheryl/PycharmProjects/Itc_data_mining/scraper.py", line 42, in catch_optional_text_value_by_xpath
    text_value = self.browser.find_element_by_xpath(x_path).text
  File "/Users/Sheryl/PycharmProjects/Itc_data_mining/data_mining/lib/python3.6/site-packages/selenium/webdriver/remote/webdriver.py", line 394, in find_element_by_xpath
    return self.find_element(by=By.XPATH, value=xpath)
  File "/Users/Sheryl/PycharmProjects/Itc_data_mining/data_mining/lib/python3.6/site-packages/selenium/webdriver/remote/webdriver.py", line 978, in find_element
    'value': value})['value']
  File "/Users/Sheryl/PycharmProjects/Itc_data_mining/data_mining/lib/python3.6/site-packages/selenium/webdriver/remote/webdriver.py", line 321, in execute
    self.error_handler.check_response(response)
  File "/Users/Sheryl/PycharmProjects/Itc_data_mining/data_mining/lib/python3.6/site-packages/selenium/webdriver/remote/errorhandler.py", line 242, in check_response
    raise exception_class(message, screen, stacktrace)
selenium.common.exceptions.NoSuchElementException: Message: Unable to locate element: //div[@class="infoEntity"]//label[text()="Competitors"]//following-sibling::*

2020-07-20 17:12:48 - root - INFO - Insert company to DB successfully
2020-07-20 17:12:48 - root - INFO - Insert job to DB successfully
2020-07-20 17:13:16 - root - ERROR - There is a problem with catching text from xpath
Traceback (most recent call last):
  File "/Users/Sheryl/PycharmProjects/Itc_data_mining/scraper.py", line 42, in catch_optional_text_value_by_xpath
    text_value = self.browser.find_element_by_xpath(x_path).text
  File "/Users/Sheryl/PycharmProjects/Itc_data_mining/data_mining/lib/python3.6/site-packages/selenium/webdriver/remote/webdriver.py", line 394, in find_element_by_xpath
    return self.find_element(by=By.XPATH, value=xpath)
  File "/Users/Sheryl/PycharmProjects/Itc_data_mining/data_mining/lib/python3.6/site-packages/selenium/webdriver/remote/webdriver.py", line 978, in find_element
    'value': value})['value']
  File "/Users/Sheryl/PycharmProjects/Itc_data_mining/data_mining/lib/python3.6/site-packages/selenium/webdriver/remote/webdriver.py", line 321, in execute
    self.error_handler.check_response(response)
  File "/Users/Sheryl/PycharmProjects/Itc_data_mining/data_mining/lib/python3.6/site-packages/selenium/webdriver/remote/errorhandler.py", line 242, in check_response
    raise exception_class(message, screen, stacktrace)
selenium.common.exceptions.NoSuchElementException: Message: Unable to locate element: //div[@class="infoEntity"]//label[text()="Competitors"]//following-sibling::*

2020-07-20 17:13:16 - root - INFO - Insert company to DB successfully
2020-07-20 17:13:16 - root - INFO - Insert job to DB successfully
2020-07-20 17:13:47 - root - ERROR - There is a problem with catching text from xpath
Traceback (most recent call last):
  File "/Users/Sheryl/PycharmProjects/Itc_data_mining/scraper.py", line 42, in catch_optional_text_value_by_xpath
    text_value = self.browser.find_element_by_xpath(x_path).text
  File "/Users/Sheryl/PycharmProjects/Itc_data_mining/data_mining/lib/python3.6/site-packages/selenium/webdriver/remote/webdriver.py", line 394, in find_element_by_xpath
    return self.find_element(by=By.XPATH, value=xpath)
  File "/Users/Sheryl/PycharmProjects/Itc_data_mining/data_mining/lib/python3.6/site-packages/selenium/webdriver/remote/webdriver.py", line 978, in find_element
    'value': value})['value']
  File "/Users/Sheryl/PycharmProjects/Itc_data_mining/data_mining/lib/python3.6/site-packages/selenium/webdriver/remote/webdriver.py", line 321, in execute
    self.error_handler.check_response(response)
  File "/Users/Sheryl/PycharmProjects/Itc_data_mining/data_mining/lib/python3.6/site-packages/selenium/webdriver/remote/errorhandler.py", line 242, in check_response
    raise exception_class(message, screen, stacktrace)
selenium.common.exceptions.NoSuchElementException: Message: Unable to locate element: //div[@class="infoEntity"]//label[text()="Founded"]//following-sibling::*

2020-07-20 17:13:47 - root - ERROR - There is a problem with catching text from xpath
Traceback (most recent call last):
  File "/Users/Sheryl/PycharmProjects/Itc_data_mining/scraper.py", line 42, in catch_optional_text_value_by_xpath
    text_value = self.browser.find_element_by_xpath(x_path).text
  File "/Users/Sheryl/PycharmProjects/Itc_data_mining/data_mining/lib/python3.6/site-packages/selenium/webdriver/remote/webdriver.py", line 394, in find_element_by_xpath
    return self.find_element(by=By.XPATH, value=xpath)
  File "/Users/Sheryl/PycharmProjects/Itc_data_mining/data_mining/lib/python3.6/site-packages/selenium/webdriver/remote/webdriver.py", line 978, in find_element
    'value': value})['value']
  File "/Users/Sheryl/PycharmProjects/Itc_data_mining/data_mining/lib/python3.6/site-packages/selenium/webdriver/remote/webdriver.py", line 321, in execute
    self.error_handler.check_response(response)
  File "/Users/Sheryl/PycharmProjects/Itc_data_mining/data_mining/lib/python3.6/site-packages/selenium/webdriver/remote/errorhandler.py", line 242, in check_response
    raise exception_class(message, screen, stacktrace)
selenium.common.exceptions.NoSuchElementException: Message: Unable to locate element: //div[@class="infoEntity"]//label[text()="Industry"]//following-sibling::*

2020-07-20 17:13:47 - root - ERROR - There is a problem with catching text from xpath
Traceback (most recent call last):
  File "/Users/Sheryl/PycharmProjects/Itc_data_mining/scraper.py", line 42, in catch_optional_text_value_by_xpath
    text_value = self.browser.find_element_by_xpath(x_path).text
  File "/Users/Sheryl/PycharmProjects/Itc_data_mining/data_mining/lib/python3.6/site-packages/selenium/webdriver/remote/webdriver.py", line 394, in find_element_by_xpath
    return self.find_element(by=By.XPATH, value=xpath)
  File "/Users/Sheryl/PycharmProjects/Itc_data_mining/data_mining/lib/python3.6/site-packages/selenium/webdriver/remote/webdriver.py", line 978, in find_element
    'value': value})['value']
  File "/Users/Sheryl/PycharmProjects/Itc_data_mining/data_mining/lib/python3.6/site-packages/selenium/webdriver/remote/webdriver.py", line 321, in execute
    self.error_handler.check_response(response)
  File "/Users/Sheryl/PycharmProjects/Itc_data_mining/data_mining/lib/python3.6/site-packages/selenium/webdriver/remote/errorhandler.py", line 242, in check_response
    raise exception_class(message, screen, stacktrace)
selenium.common.exceptions.NoSuchElementException: Message: Unable to locate element: //div[@class="infoEntity"]//label[text()="Sector"]//following-sibling::*

2020-07-20 17:13:47 - root - ERROR - There is a problem with catching text from xpath
Traceback (most recent call last):
  File "/Users/Sheryl/PycharmProjects/Itc_data_mining/scraper.py", line 42, in catch_optional_text_value_by_xpath
    text_value = self.browser.find_element_by_xpath(x_path).text
  File "/Users/Sheryl/PycharmProjects/Itc_data_mining/data_mining/lib/python3.6/site-packages/selenium/webdriver/remote/webdriver.py", line 394, in find_element_by_xpath
    return self.find_element(by=By.XPATH, value=xpath)
  File "/Users/Sheryl/PycharmProjects/Itc_data_mining/data_mining/lib/python3.6/site-packages/selenium/webdriver/remote/webdriver.py", line 978, in find_element
    'value': value})['value']
  File "/Users/Sheryl/PycharmProjects/Itc_data_mining/data_mining/lib/python3.6/site-packages/selenium/webdriver/remote/webdriver.py", line 321, in execute
    self.error_handler.check_response(response)
  File "/Users/Sheryl/PycharmProjects/Itc_data_mining/data_mining/lib/python3.6/site-packages/selenium/webdriver/remote/errorhandler.py", line 242, in check_response
    raise exception_class(message, screen, stacktrace)
selenium.common.exceptions.NoSuchElementException: Message: Unable to locate element: //div[@class="infoEntity"]//label[text()="Competitors"]//following-sibling::*

2020-07-20 17:13:47 - root - INFO - Insert company to DB successfully
2020-07-20 17:13:47 - root - INFO - Insert job to DB successfully
2020-07-20 17:14:16 - root - ERROR - There is a problem with catching text from xpath
Traceback (most recent call last):
  File "/Users/Sheryl/PycharmProjects/Itc_data_mining/scraper.py", line 42, in catch_optional_text_value_by_xpath
    text_value = self.browser.find_element_by_xpath(x_path).text
  File "/Users/Sheryl/PycharmProjects/Itc_data_mining/data_mining/lib/python3.6/site-packages/selenium/webdriver/remote/webdriver.py", line 394, in find_element_by_xpath
    return self.find_element(by=By.XPATH, value=xpath)
  File "/Users/Sheryl/PycharmProjects/Itc_data_mining/data_mining/lib/python3.6/site-packages/selenium/webdriver/remote/webdriver.py", line 978, in find_element
    'value': value})['value']
  File "/Users/Sheryl/PycharmProjects/Itc_data_mining/data_mining/lib/python3.6/site-packages/selenium/webdriver/remote/webdriver.py", line 321, in execute
    self.error_handler.check_response(response)
  File "/Users/Sheryl/PycharmProjects/Itc_data_mining/data_mining/lib/python3.6/site-packages/selenium/webdriver/remote/errorhandler.py", line 242, in check_response
    raise exception_class(message, screen, stacktrace)
selenium.common.exceptions.NoSuchElementException: Message: Unable to locate element: //div[@class="infoEntity"]//label[text()="Founded"]//following-sibling::*

2020-07-20 17:14:16 - root - ERROR - There is a problem with catching text from xpath
Traceback (most recent call last):
  File "/Users/Sheryl/PycharmProjects/Itc_data_mining/scraper.py", line 42, in catch_optional_text_value_by_xpath
    text_value = self.browser.find_element_by_xpath(x_path).text
  File "/Users/Sheryl/PycharmProjects/Itc_data_mining/data_mining/lib/python3.6/site-packages/selenium/webdriver/remote/webdriver.py", line 394, in find_element_by_xpath
    return self.find_element(by=By.XPATH, value=xpath)
  File "/Users/Sheryl/PycharmProjects/Itc_data_mining/data_mining/lib/python3.6/site-packages/selenium/webdriver/remote/webdriver.py", line 978, in find_element
    'value': value})['value']
  File "/Users/Sheryl/PycharmProjects/Itc_data_mining/data_mining/lib/python3.6/site-packages/selenium/webdriver/remote/webdriver.py", line 321, in execute
    self.error_handler.check_response(response)
  File "/Users/Sheryl/PycharmProjects/Itc_data_mining/data_mining/lib/python3.6/site-packages/selenium/webdriver/remote/errorhandler.py", line 242, in check_response
    raise exception_class(message, screen, stacktrace)
selenium.common.exceptions.NoSuchElementException: Message: Unable to locate element: //div[@class="infoEntity"]//label[text()="Industry"]//following-sibling::*

2020-07-20 17:14:16 - root - ERROR - There is a problem with catching text from xpath
Traceback (most recent call last):
  File "/Users/Sheryl/PycharmProjects/Itc_data_mining/scraper.py", line 42, in catch_optional_text_value_by_xpath
    text_value = self.browser.find_element_by_xpath(x_path).text
  File "/Users/Sheryl/PycharmProjects/Itc_data_mining/data_mining/lib/python3.6/site-packages/selenium/webdriver/remote/webdriver.py", line 394, in find_element_by_xpath
    return self.find_element(by=By.XPATH, value=xpath)
  File "/Users/Sheryl/PycharmProjects/Itc_data_mining/data_mining/lib/python3.6/site-packages/selenium/webdriver/remote/webdriver.py", line 978, in find_element
    'value': value})['value']
  File "/Users/Sheryl/PycharmProjects/Itc_data_mining/data_mining/lib/python3.6/site-packages/selenium/webdriver/remote/webdriver.py", line 321, in execute
    self.error_handler.check_response(response)
  File "/Users/Sheryl/PycharmProjects/Itc_data_mining/data_mining/lib/python3.6/site-packages/selenium/webdriver/remote/errorhandler.py", line 242, in check_response
    raise exception_class(message, screen, stacktrace)
selenium.common.exceptions.NoSuchElementException: Message: Unable to locate element: //div[@class="infoEntity"]//label[text()="Sector"]//following-sibling::*

2020-07-20 17:14:16 - root - ERROR - There is a problem with catching text from xpath
Traceback (most recent call last):
  File "/Users/Sheryl/PycharmProjects/Itc_data_mining/scraper.py", line 42, in catch_optional_text_value_by_xpath
    text_value = self.browser.find_element_by_xpath(x_path).text
  File "/Users/Sheryl/PycharmProjects/Itc_data_mining/data_mining/lib/python3.6/site-packages/selenium/webdriver/remote/webdriver.py", line 394, in find_element_by_xpath
    return self.find_element(by=By.XPATH, value=xpath)
  File "/Users/Sheryl/PycharmProjects/Itc_data_mining/data_mining/lib/python3.6/site-packages/selenium/webdriver/remote/webdriver.py", line 978, in find_element
    'value': value})['value']
  File "/Users/Sheryl/PycharmProjects/Itc_data_mining/data_mining/lib/python3.6/site-packages/selenium/webdriver/remote/webdriver.py", line 321, in execute
    self.error_handler.check_response(response)
  File "/Users/Sheryl/PycharmProjects/Itc_data_mining/data_mining/lib/python3.6/site-packages/selenium/webdriver/remote/errorhandler.py", line 242, in check_response
    raise exception_class(message, screen, stacktrace)
selenium.common.exceptions.NoSuchElementException: Message: Unable to locate element: //div[@class="infoEntity"]//label[text()="Competitors"]//following-sibling::*

2020-07-20 17:14:16 - root - INFO - Insert company to DB successfully
2020-07-20 17:14:16 - root - INFO - Insert job to DB successfully
2020-07-20 17:14:45 - root - ERROR - There is a problem with catching text from xpath
Traceback (most recent call last):
  File "/Users/Sheryl/PycharmProjects/Itc_data_mining/scraper.py", line 42, in catch_optional_text_value_by_xpath
    text_value = self.browser.find_element_by_xpath(x_path).text
  File "/Users/Sheryl/PycharmProjects/Itc_data_mining/data_mining/lib/python3.6/site-packages/selenium/webdriver/remote/webdriver.py", line 394, in find_element_by_xpath
    return self.find_element(by=By.XPATH, value=xpath)
  File "/Users/Sheryl/PycharmProjects/Itc_data_mining/data_mining/lib/python3.6/site-packages/selenium/webdriver/remote/webdriver.py", line 978, in find_element
    'value': value})['value']
  File "/Users/Sheryl/PycharmProjects/Itc_data_mining/data_mining/lib/python3.6/site-packages/selenium/webdriver/remote/webdriver.py", line 321, in execute
    self.error_handler.check_response(response)
  File "/Users/Sheryl/PycharmProjects/Itc_data_mining/data_mining/lib/python3.6/site-packages/selenium/webdriver/remote/errorhandler.py", line 242, in check_response
    raise exception_class(message, screen, stacktrace)
selenium.common.exceptions.NoSuchElementException: Message: Unable to locate element: //div[@class="infoEntity"]//label[text()="Founded"]//following-sibling::*

2020-07-20 17:14:45 - root - ERROR - There is a problem with catching text from xpath
Traceback (most recent call last):
  File "/Users/Sheryl/PycharmProjects/Itc_data_mining/scraper.py", line 42, in catch_optional_text_value_by_xpath
    text_value = self.browser.find_element_by_xpath(x_path).text
  File "/Users/Sheryl/PycharmProjects/Itc_data_mining/data_mining/lib/python3.6/site-packages/selenium/webdriver/remote/webdriver.py", line 394, in find_element_by_xpath
    return self.find_element(by=By.XPATH, value=xpath)
  File "/Users/Sheryl/PycharmProjects/Itc_data_mining/data_mining/lib/python3.6/site-packages/selenium/webdriver/remote/webdriver.py", line 978, in find_element
    'value': value})['value']
  File "/Users/Sheryl/PycharmProjects/Itc_data_mining/data_mining/lib/python3.6/site-packages/selenium/webdriver/remote/webdriver.py", line 321, in execute
    self.error_handler.check_response(response)
  File "/Users/Sheryl/PycharmProjects/Itc_data_mining/data_mining/lib/python3.6/site-packages/selenium/webdriver/remote/errorhandler.py", line 242, in check_response
    raise exception_class(message, screen, stacktrace)
selenium.common.exceptions.NoSuchElementException: Message: Unable to locate element: //div[@class="infoEntity"]//label[text()="Industry"]//following-sibling::*

2020-07-20 17:14:45 - root - ERROR - There is a problem with catching text from xpath
Traceback (most recent call last):
  File "/Users/Sheryl/PycharmProjects/Itc_data_mining/scraper.py", line 42, in catch_optional_text_value_by_xpath
    text_value = self.browser.find_element_by_xpath(x_path).text
  File "/Users/Sheryl/PycharmProjects/Itc_data_mining/data_mining/lib/python3.6/site-packages/selenium/webdriver/remote/webdriver.py", line 394, in find_element_by_xpath
    return self.find_element(by=By.XPATH, value=xpath)
  File "/Users/Sheryl/PycharmProjects/Itc_data_mining/data_mining/lib/python3.6/site-packages/selenium/webdriver/remote/webdriver.py", line 978, in find_element
    'value': value})['value']
  File "/Users/Sheryl/PycharmProjects/Itc_data_mining/data_mining/lib/python3.6/site-packages/selenium/webdriver/remote/webdriver.py", line 321, in execute
    self.error_handler.check_response(response)
  File "/Users/Sheryl/PycharmProjects/Itc_data_mining/data_mining/lib/python3.6/site-packages/selenium/webdriver/remote/errorhandler.py", line 242, in check_response
    raise exception_class(message, screen, stacktrace)
selenium.common.exceptions.NoSuchElementException: Message: Unable to locate element: //div[@class="infoEntity"]//label[text()="Sector"]//following-sibling::*

2020-07-20 17:14:45 - root - ERROR - There is a problem with catching text from xpath
Traceback (most recent call last):
  File "/Users/Sheryl/PycharmProjects/Itc_data_mining/scraper.py", line 42, in catch_optional_text_value_by_xpath
    text_value = self.browser.find_element_by_xpath(x_path).text
  File "/Users/Sheryl/PycharmProjects/Itc_data_mining/data_mining/lib/python3.6/site-packages/selenium/webdriver/remote/webdriver.py", line 394, in find_element_by_xpath
    return self.find_element(by=By.XPATH, value=xpath)
  File "/Users/Sheryl/PycharmProjects/Itc_data_mining/data_mining/lib/python3.6/site-packages/selenium/webdriver/remote/webdriver.py", line 978, in find_element
    'value': value})['value']
  File "/Users/Sheryl/PycharmProjects/Itc_data_mining/data_mining/lib/python3.6/site-packages/selenium/webdriver/remote/webdriver.py", line 321, in execute
    self.error_handler.check_response(response)
  File "/Users/Sheryl/PycharmProjects/Itc_data_mining/data_mining/lib/python3.6/site-packages/selenium/webdriver/remote/errorhandler.py", line 242, in check_response
    raise exception_class(message, screen, stacktrace)
selenium.common.exceptions.NoSuchElementException: Message: Unable to locate element: //div[@class="infoEntity"]//label[text()="Competitors"]//following-sibling::*

2020-07-20 17:14:45 - root - INFO - Insert company to DB successfully
2020-07-20 17:14:45 - root - INFO - Insert job to DB successfully
2020-07-20 17:15:15 - root - ERROR - There is a problem with catching text from xpath
Traceback (most recent call last):
  File "/Users/Sheryl/PycharmProjects/Itc_data_mining/scraper.py", line 42, in catch_optional_text_value_by_xpath
    text_value = self.browser.find_element_by_xpath(x_path).text
  File "/Users/Sheryl/PycharmProjects/Itc_data_mining/data_mining/lib/python3.6/site-packages/selenium/webdriver/remote/webdriver.py", line 394, in find_element_by_xpath
    return self.find_element(by=By.XPATH, value=xpath)
  File "/Users/Sheryl/PycharmProjects/Itc_data_mining/data_mining/lib/python3.6/site-packages/selenium/webdriver/remote/webdriver.py", line 978, in find_element
    'value': value})['value']
  File "/Users/Sheryl/PycharmProjects/Itc_data_mining/data_mining/lib/python3.6/site-packages/selenium/webdriver/remote/webdriver.py", line 321, in execute
    self.error_handler.check_response(response)
  File "/Users/Sheryl/PycharmProjects/Itc_data_mining/data_mining/lib/python3.6/site-packages/selenium/webdriver/remote/errorhandler.py", line 242, in check_response
    raise exception_class(message, screen, stacktrace)
selenium.common.exceptions.NoSuchElementException: Message: Unable to locate element: //div[@class="infoEntity"]//label[text()="Founded"]//following-sibling::*

2020-07-20 17:15:15 - root - ERROR - There is a problem with catching text from xpath
Traceback (most recent call last):
  File "/Users/Sheryl/PycharmProjects/Itc_data_mining/scraper.py", line 42, in catch_optional_text_value_by_xpath
    text_value = self.browser.find_element_by_xpath(x_path).text
  File "/Users/Sheryl/PycharmProjects/Itc_data_mining/data_mining/lib/python3.6/site-packages/selenium/webdriver/remote/webdriver.py", line 394, in find_element_by_xpath
    return self.find_element(by=By.XPATH, value=xpath)
  File "/Users/Sheryl/PycharmProjects/Itc_data_mining/data_mining/lib/python3.6/site-packages/selenium/webdriver/remote/webdriver.py", line 978, in find_element
    'value': value})['value']
  File "/Users/Sheryl/PycharmProjects/Itc_data_mining/data_mining/lib/python3.6/site-packages/selenium/webdriver/remote/webdriver.py", line 321, in execute
    self.error_handler.check_response(response)
  File "/Users/Sheryl/PycharmProjects/Itc_data_mining/data_mining/lib/python3.6/site-packages/selenium/webdriver/remote/errorhandler.py", line 242, in check_response
    raise exception_class(message, screen, stacktrace)
selenium.common.exceptions.NoSuchElementException: Message: Unable to locate element: //div[@class="infoEntity"]//label[text()="Industry"]//following-sibling::*

2020-07-20 17:15:15 - root - ERROR - There is a problem with catching text from xpath
Traceback (most recent call last):
  File "/Users/Sheryl/PycharmProjects/Itc_data_mining/scraper.py", line 42, in catch_optional_text_value_by_xpath
    text_value = self.browser.find_element_by_xpath(x_path).text
  File "/Users/Sheryl/PycharmProjects/Itc_data_mining/data_mining/lib/python3.6/site-packages/selenium/webdriver/remote/webdriver.py", line 394, in find_element_by_xpath
    return self.find_element(by=By.XPATH, value=xpath)
  File "/Users/Sheryl/PycharmProjects/Itc_data_mining/data_mining/lib/python3.6/site-packages/selenium/webdriver/remote/webdriver.py", line 978, in find_element
    'value': value})['value']
  File "/Users/Sheryl/PycharmProjects/Itc_data_mining/data_mining/lib/python3.6/site-packages/selenium/webdriver/remote/webdriver.py", line 321, in execute
    self.error_handler.check_response(response)
  File "/Users/Sheryl/PycharmProjects/Itc_data_mining/data_mining/lib/python3.6/site-packages/selenium/webdriver/remote/errorhandler.py", line 242, in check_response
    raise exception_class(message, screen, stacktrace)
selenium.common.exceptions.NoSuchElementException: Message: Unable to locate element: //div[@class="infoEntity"]//label[text()="Sector"]//following-sibling::*

2020-07-20 17:15:15 - root - ERROR - There is a problem with catching text from xpath
Traceback (most recent call last):
  File "/Users/Sheryl/PycharmProjects/Itc_data_mining/scraper.py", line 42, in catch_optional_text_value_by_xpath
    text_value = self.browser.find_element_by_xpath(x_path).text
  File "/Users/Sheryl/PycharmProjects/Itc_data_mining/data_mining/lib/python3.6/site-packages/selenium/webdriver/remote/webdriver.py", line 394, in find_element_by_xpath
    return self.find_element(by=By.XPATH, value=xpath)
  File "/Users/Sheryl/PycharmProjects/Itc_data_mining/data_mining/lib/python3.6/site-packages/selenium/webdriver/remote/webdriver.py", line 978, in find_element
    'value': value})['value']
  File "/Users/Sheryl/PycharmProjects/Itc_data_mining/data_mining/lib/python3.6/site-packages/selenium/webdriver/remote/webdriver.py", line 321, in execute
    self.error_handler.check_response(response)
  File "/Users/Sheryl/PycharmProjects/Itc_data_mining/data_mining/lib/python3.6/site-packages/selenium/webdriver/remote/errorhandler.py", line 242, in check_response
    raise exception_class(message, screen, stacktrace)
selenium.common.exceptions.NoSuchElementException: Message: Unable to locate element: //div[@class="infoEntity"]//label[text()="Competitors"]//following-sibling::*

2020-07-20 17:15:15 - root - INFO - Insert company to DB successfully
2020-07-20 17:15:15 - root - INFO - Insert job to DB successfully
2020-07-20 17:15:45 - root - INFO - Insert company to DB successfully
2020-07-20 17:15:45 - root - INFO - Get information from DB
2020-07-20 17:16:02 - root - INFO - Browser connect to URL
2020-07-20 17:16:04 - root - INFO - Search for competitor's company page
2020-07-20 17:16:04 - root - ERROR - No popup to close
Traceback (most recent call last):
  File "/Users/Sheryl/PycharmProjects/Itc_data_mining/scraper.py", line 28, in close_popup
    pop_up = self.browser.find_element_by_xpath(cst.POP_UP_XPATH)
  File "/Users/Sheryl/PycharmProjects/Itc_data_mining/data_mining/lib/python3.6/site-packages/selenium/webdriver/remote/webdriver.py", line 394, in find_element_by_xpath
    return self.find_element(by=By.XPATH, value=xpath)
  File "/Users/Sheryl/PycharmProjects/Itc_data_mining/data_mining/lib/python3.6/site-packages/selenium/webdriver/remote/webdriver.py", line 978, in find_element
    'value': value})['value']
  File "/Users/Sheryl/PycharmProjects/Itc_data_mining/data_mining/lib/python3.6/site-packages/selenium/webdriver/remote/webdriver.py", line 321, in execute
    self.error_handler.check_response(response)
  File "/Users/Sheryl/PycharmProjects/Itc_data_mining/data_mining/lib/python3.6/site-packages/selenium/webdriver/remote/errorhandler.py", line 242, in check_response
    raise exception_class(message, screen, stacktrace)
selenium.common.exceptions.NoSuchElementException: Message: Unable to locate element: //div[contains(@class,'modal_main')]//span[@class='SVGInline modal_closeIcon']

2020-07-20 17:16:12 - root - INFO - Browser connect to new URL of a company
2020-07-20 17:16:31 - root - INFO - Close browser successfully
2020-07-20 17:16:31 - root - INFO - Insert company to DB successfully
2020-07-20 17:16:31 - root - INFO - Insert competitors to DB successfully
2020-07-20 17:16:31 - root - INFO - Get information from DB
2020-07-20 17:16:51 - root - INFO - Browser connect to URL
2020-07-20 17:16:52 - root - INFO - Search for competitor's company page
2020-07-20 17:16:52 - root - ERROR - No popup to close
Traceback (most recent call last):
  File "/Users/Sheryl/PycharmProjects/Itc_data_mining/scraper.py", line 28, in close_popup
    pop_up = self.browser.find_element_by_xpath(cst.POP_UP_XPATH)
  File "/Users/Sheryl/PycharmProjects/Itc_data_mining/data_mining/lib/python3.6/site-packages/selenium/webdriver/remote/webdriver.py", line 394, in find_element_by_xpath
    return self.find_element(by=By.XPATH, value=xpath)
  File "/Users/Sheryl/PycharmProjects/Itc_data_mining/data_mining/lib/python3.6/site-packages/selenium/webdriver/remote/webdriver.py", line 978, in find_element
    'value': value})['value']
  File "/Users/Sheryl/PycharmProjects/Itc_data_mining/data_mining/lib/python3.6/site-packages/selenium/webdriver/remote/webdriver.py", line 321, in execute
    self.error_handler.check_response(response)
  File "/Users/Sheryl/PycharmProjects/Itc_data_mining/data_mining/lib/python3.6/site-packages/selenium/webdriver/remote/errorhandler.py", line 242, in check_response
    raise exception_class(message, screen, stacktrace)
selenium.common.exceptions.NoSuchElementException: Message: Unable to locate element: //div[contains(@class,'modal_main')]//span[@class='SVGInline modal_closeIcon']

2020-07-20 17:16:57 - root - INFO - Browser connect to new URL of a company
2020-07-20 17:17:16 - root - INFO - Close browser successfully
2020-07-20 17:17:16 - root - INFO - Insert company to DB successfully
2020-07-20 17:17:16 - root - INFO - Insert competitors to DB successfully
2020-07-20 17:17:16 - root - INFO - Get information from DB
2020-07-20 17:17:39 - root - INFO - Browser connect to URL
2020-07-20 17:17:42 - root - INFO - Search for competitor's company page
2020-07-20 17:17:42 - root - ERROR - No popup to close
Traceback (most recent call last):
  File "/Users/Sheryl/PycharmProjects/Itc_data_mining/scraper.py", line 28, in close_popup
    pop_up = self.browser.find_element_by_xpath(cst.POP_UP_XPATH)
  File "/Users/Sheryl/PycharmProjects/Itc_data_mining/data_mining/lib/python3.6/site-packages/selenium/webdriver/remote/webdriver.py", line 394, in find_element_by_xpath
    return self.find_element(by=By.XPATH, value=xpath)
  File "/Users/Sheryl/PycharmProjects/Itc_data_mining/data_mining/lib/python3.6/site-packages/selenium/webdriver/remote/webdriver.py", line 978, in find_element
    'value': value})['value']
  File "/Users/Sheryl/PycharmProjects/Itc_data_mining/data_mining/lib/python3.6/site-packages/selenium/webdriver/remote/webdriver.py", line 321, in execute
    self.error_handler.check_response(response)
  File "/Users/Sheryl/PycharmProjects/Itc_data_mining/data_mining/lib/python3.6/site-packages/selenium/webdriver/remote/errorhandler.py", line 242, in check_response
    raise exception_class(message, screen, stacktrace)
selenium.common.exceptions.NoSuchElementException: Message: Unable to locate element: //div[contains(@class,'modal_main')]//span[@class='SVGInline modal_closeIcon']

2020-07-20 17:17:55 - root - INFO - Browser connect to new URL of a company
2020-07-20 17:18:13 - root - INFO - Close browser successfully
2020-07-20 17:18:13 - root - INFO - Insert company to DB successfully
2020-07-20 17:18:13 - root - INFO - Insert competitors to DB successfully
2020-07-20 17:18:13 - root - INFO - Insert job to DB successfully
2020-07-20 17:18:43 - root - ERROR - There is a problem with catching text from xpath
Traceback (most recent call last):
  File "/Users/Sheryl/PycharmProjects/Itc_data_mining/scraper.py", line 42, in catch_optional_text_value_by_xpath
    text_value = self.browser.find_element_by_xpath(x_path).text
  File "/Users/Sheryl/PycharmProjects/Itc_data_mining/data_mining/lib/python3.6/site-packages/selenium/webdriver/remote/webdriver.py", line 394, in find_element_by_xpath
    return self.find_element(by=By.XPATH, value=xpath)
  File "/Users/Sheryl/PycharmProjects/Itc_data_mining/data_mining/lib/python3.6/site-packages/selenium/webdriver/remote/webdriver.py", line 978, in find_element
    'value': value})['value']
  File "/Users/Sheryl/PycharmProjects/Itc_data_mining/data_mining/lib/python3.6/site-packages/selenium/webdriver/remote/webdriver.py", line 321, in execute
    self.error_handler.check_response(response)
  File "/Users/Sheryl/PycharmProjects/Itc_data_mining/data_mining/lib/python3.6/site-packages/selenium/webdriver/remote/errorhandler.py", line 242, in check_response
    raise exception_class(message, screen, stacktrace)
selenium.common.exceptions.NoSuchElementException: Message: Unable to locate element: //div[@class="infoEntity"]//label[text()="Competitors"]//following-sibling::*

2020-07-20 17:18:43 - root - INFO - Insert company to DB successfully
2020-07-20 17:18:43 - root - INFO - Insert job to DB successfully
2020-07-20 17:19:12 - root - INFO - Insert company to DB successfully
2020-07-20 17:19:12 - root - INFO - Get information from DB
2020-07-20 17:19:32 - root - INFO - Browser connect to URL
2020-07-20 17:19:33 - root - INFO - Search for competitor's company page
2020-07-20 17:19:33 - root - ERROR - No popup to close
Traceback (most recent call last):
  File "/Users/Sheryl/PycharmProjects/Itc_data_mining/scraper.py", line 28, in close_popup
    pop_up = self.browser.find_element_by_xpath(cst.POP_UP_XPATH)
  File "/Users/Sheryl/PycharmProjects/Itc_data_mining/data_mining/lib/python3.6/site-packages/selenium/webdriver/remote/webdriver.py", line 394, in find_element_by_xpath
    return self.find_element(by=By.XPATH, value=xpath)
  File "/Users/Sheryl/PycharmProjects/Itc_data_mining/data_mining/lib/python3.6/site-packages/selenium/webdriver/remote/webdriver.py", line 978, in find_element
    'value': value})['value']
  File "/Users/Sheryl/PycharmProjects/Itc_data_mining/data_mining/lib/python3.6/site-packages/selenium/webdriver/remote/webdriver.py", line 321, in execute
    self.error_handler.check_response(response)
  File "/Users/Sheryl/PycharmProjects/Itc_data_mining/data_mining/lib/python3.6/site-packages/selenium/webdriver/remote/errorhandler.py", line 242, in check_response
    raise exception_class(message, screen, stacktrace)
selenium.common.exceptions.NoSuchElementException: Message: Unable to locate element: //div[contains(@class,'modal_main')]//span[@class='SVGInline modal_closeIcon']

2020-07-20 17:19:41 - root - INFO - Browser connect to new URL of a company
2020-07-20 17:20:00 - root - INFO - Close browser successfully
2020-07-20 17:20:00 - root - INFO - Insert company to DB successfully
2020-07-20 17:20:00 - root - INFO - Insert competitors to DB successfully
2020-07-20 17:20:00 - root - INFO - Get information from DB
2020-07-20 17:20:09 - root - INFO - Browser connect to URL
2020-07-20 17:20:11 - root - INFO - Search for competitor's company page
2020-07-20 17:20:11 - root - ERROR - No popup to close
Traceback (most recent call last):
  File "/Users/Sheryl/PycharmProjects/Itc_data_mining/scraper.py", line 28, in close_popup
    pop_up = self.browser.find_element_by_xpath(cst.POP_UP_XPATH)
  File "/Users/Sheryl/PycharmProjects/Itc_data_mining/data_mining/lib/python3.6/site-packages/selenium/webdriver/remote/webdriver.py", line 394, in find_element_by_xpath
    return self.find_element(by=By.XPATH, value=xpath)
  File "/Users/Sheryl/PycharmProjects/Itc_data_mining/data_mining/lib/python3.6/site-packages/selenium/webdriver/remote/webdriver.py", line 978, in find_element
    'value': value})['value']
  File "/Users/Sheryl/PycharmProjects/Itc_data_mining/data_mining/lib/python3.6/site-packages/selenium/webdriver/remote/webdriver.py", line 321, in execute
    self.error_handler.check_response(response)
  File "/Users/Sheryl/PycharmProjects/Itc_data_mining/data_mining/lib/python3.6/site-packages/selenium/webdriver/remote/errorhandler.py", line 242, in check_response
    raise exception_class(message, screen, stacktrace)
selenium.common.exceptions.NoSuchElementException: Message: Unable to locate element: //div[contains(@class,'modal_main')]//span[@class='SVGInline modal_closeIcon']

2020-07-20 17:20:16 - root - INFO - Browser connect to new URL of a company
2020-07-20 17:20:37 - root - INFO - Close browser successfully
2020-07-20 17:20:37 - root - INFO - Insert company to DB successfully
2020-07-20 17:20:37 - root - INFO - Insert competitors to DB successfully
2020-07-20 17:20:37 - root - INFO - Insert job to DB successfully
2020-07-20 17:21:07 - root - ERROR - There is a problem with catching text from xpath
Traceback (most recent call last):
  File "/Users/Sheryl/PycharmProjects/Itc_data_mining/scraper.py", line 42, in catch_optional_text_value_by_xpath
    text_value = self.browser.find_element_by_xpath(x_path).text
  File "/Users/Sheryl/PycharmProjects/Itc_data_mining/data_mining/lib/python3.6/site-packages/selenium/webdriver/remote/webdriver.py", line 394, in find_element_by_xpath
    return self.find_element(by=By.XPATH, value=xpath)
  File "/Users/Sheryl/PycharmProjects/Itc_data_mining/data_mining/lib/python3.6/site-packages/selenium/webdriver/remote/webdriver.py", line 978, in find_element
    'value': value})['value']
  File "/Users/Sheryl/PycharmProjects/Itc_data_mining/data_mining/lib/python3.6/site-packages/selenium/webdriver/remote/webdriver.py", line 321, in execute
    self.error_handler.check_response(response)
  File "/Users/Sheryl/PycharmProjects/Itc_data_mining/data_mining/lib/python3.6/site-packages/selenium/webdriver/remote/errorhandler.py", line 242, in check_response
    raise exception_class(message, screen, stacktrace)
selenium.common.exceptions.NoSuchElementException: Message: Unable to locate element: //div[@class="infoEntity"]//label[text()="Founded"]//following-sibling::*

2020-07-20 17:21:07 - root - ERROR - There is a problem with catching text from xpath
Traceback (most recent call last):
  File "/Users/Sheryl/PycharmProjects/Itc_data_mining/scraper.py", line 42, in catch_optional_text_value_by_xpath
    text_value = self.browser.find_element_by_xpath(x_path).text
  File "/Users/Sheryl/PycharmProjects/Itc_data_mining/data_mining/lib/python3.6/site-packages/selenium/webdriver/remote/webdriver.py", line 394, in find_element_by_xpath
    return self.find_element(by=By.XPATH, value=xpath)
  File "/Users/Sheryl/PycharmProjects/Itc_data_mining/data_mining/lib/python3.6/site-packages/selenium/webdriver/remote/webdriver.py", line 978, in find_element
    'value': value})['value']
  File "/Users/Sheryl/PycharmProjects/Itc_data_mining/data_mining/lib/python3.6/site-packages/selenium/webdriver/remote/webdriver.py", line 321, in execute
    self.error_handler.check_response(response)
  File "/Users/Sheryl/PycharmProjects/Itc_data_mining/data_mining/lib/python3.6/site-packages/selenium/webdriver/remote/errorhandler.py", line 242, in check_response
    raise exception_class(message, screen, stacktrace)
selenium.common.exceptions.NoSuchElementException: Message: Unable to locate element: //div[@class="infoEntity"]//label[text()="Competitors"]//following-sibling::*

2020-07-20 17:21:07 - root - INFO - Insert company to DB successfully
2020-07-20 17:21:07 - root - INFO - Insert job to DB successfully
2020-07-20 17:21:36 - root - ERROR - There is a problem with catching text from xpath
Traceback (most recent call last):
  File "/Users/Sheryl/PycharmProjects/Itc_data_mining/scraper.py", line 42, in catch_optional_text_value_by_xpath
    text_value = self.browser.find_element_by_xpath(x_path).text
  File "/Users/Sheryl/PycharmProjects/Itc_data_mining/data_mining/lib/python3.6/site-packages/selenium/webdriver/remote/webdriver.py", line 394, in find_element_by_xpath
    return self.find_element(by=By.XPATH, value=xpath)
  File "/Users/Sheryl/PycharmProjects/Itc_data_mining/data_mining/lib/python3.6/site-packages/selenium/webdriver/remote/webdriver.py", line 978, in find_element
    'value': value})['value']
  File "/Users/Sheryl/PycharmProjects/Itc_data_mining/data_mining/lib/python3.6/site-packages/selenium/webdriver/remote/webdriver.py", line 321, in execute
    self.error_handler.check_response(response)
  File "/Users/Sheryl/PycharmProjects/Itc_data_mining/data_mining/lib/python3.6/site-packages/selenium/webdriver/remote/errorhandler.py", line 242, in check_response
    raise exception_class(message, screen, stacktrace)
selenium.common.exceptions.NoSuchElementException: Message: Unable to locate element: //div[@class="infoEntity"]//label[text()="Size"]//following-sibling::*

2020-07-20 17:21:36 - root - ERROR - There is a problem with catching text from xpath
Traceback (most recent call last):
  File "/Users/Sheryl/PycharmProjects/Itc_data_mining/scraper.py", line 42, in catch_optional_text_value_by_xpath
    text_value = self.browser.find_element_by_xpath(x_path).text
  File "/Users/Sheryl/PycharmProjects/Itc_data_mining/data_mining/lib/python3.6/site-packages/selenium/webdriver/remote/webdriver.py", line 394, in find_element_by_xpath
    return self.find_element(by=By.XPATH, value=xpath)
  File "/Users/Sheryl/PycharmProjects/Itc_data_mining/data_mining/lib/python3.6/site-packages/selenium/webdriver/remote/webdriver.py", line 978, in find_element
    'value': value})['value']
  File "/Users/Sheryl/PycharmProjects/Itc_data_mining/data_mining/lib/python3.6/site-packages/selenium/webdriver/remote/webdriver.py", line 321, in execute
    self.error_handler.check_response(response)
  File "/Users/Sheryl/PycharmProjects/Itc_data_mining/data_mining/lib/python3.6/site-packages/selenium/webdriver/remote/errorhandler.py", line 242, in check_response
    raise exception_class(message, screen, stacktrace)
selenium.common.exceptions.NoSuchElementException: Message: Unable to locate element: //div[@class="infoEntity"]//label[text()="Founded"]//following-sibling::*

2020-07-20 17:21:36 - root - ERROR - There is a problem with catching text from xpath
Traceback (most recent call last):
  File "/Users/Sheryl/PycharmProjects/Itc_data_mining/scraper.py", line 42, in catch_optional_text_value_by_xpath
    text_value = self.browser.find_element_by_xpath(x_path).text
  File "/Users/Sheryl/PycharmProjects/Itc_data_mining/data_mining/lib/python3.6/site-packages/selenium/webdriver/remote/webdriver.py", line 394, in find_element_by_xpath
    return self.find_element(by=By.XPATH, value=xpath)
  File "/Users/Sheryl/PycharmProjects/Itc_data_mining/data_mining/lib/python3.6/site-packages/selenium/webdriver/remote/webdriver.py", line 978, in find_element
    'value': value})['value']
  File "/Users/Sheryl/PycharmProjects/Itc_data_mining/data_mining/lib/python3.6/site-packages/selenium/webdriver/remote/webdriver.py", line 321, in execute
    self.error_handler.check_response(response)
  File "/Users/Sheryl/PycharmProjects/Itc_data_mining/data_mining/lib/python3.6/site-packages/selenium/webdriver/remote/errorhandler.py", line 242, in check_response
    raise exception_class(message, screen, stacktrace)
selenium.common.exceptions.NoSuchElementException: Message: Unable to locate element: //div[@class="infoEntity"]//label[text()="Industry"]//following-sibling::*

2020-07-20 17:21:36 - root - ERROR - There is a problem with catching text from xpath
Traceback (most recent call last):
  File "/Users/Sheryl/PycharmProjects/Itc_data_mining/scraper.py", line 42, in catch_optional_text_value_by_xpath
    text_value = self.browser.find_element_by_xpath(x_path).text
  File "/Users/Sheryl/PycharmProjects/Itc_data_mining/data_mining/lib/python3.6/site-packages/selenium/webdriver/remote/webdriver.py", line 394, in find_element_by_xpath
    return self.find_element(by=By.XPATH, value=xpath)
  File "/Users/Sheryl/PycharmProjects/Itc_data_mining/data_mining/lib/python3.6/site-packages/selenium/webdriver/remote/webdriver.py", line 978, in find_element
    'value': value})['value']
  File "/Users/Sheryl/PycharmProjects/Itc_data_mining/data_mining/lib/python3.6/site-packages/selenium/webdriver/remote/webdriver.py", line 321, in execute
    self.error_handler.check_response(response)
  File "/Users/Sheryl/PycharmProjects/Itc_data_mining/data_mining/lib/python3.6/site-packages/selenium/webdriver/remote/errorhandler.py", line 242, in check_response
    raise exception_class(message, screen, stacktrace)
selenium.common.exceptions.NoSuchElementException: Message: Unable to locate element: //div[@class="infoEntity"]//label[text()="Sector"]//following-sibling::*

2020-07-20 17:21:36 - root - ERROR - There is a problem with catching text from xpath
Traceback (most recent call last):
  File "/Users/Sheryl/PycharmProjects/Itc_data_mining/scraper.py", line 42, in catch_optional_text_value_by_xpath
    text_value = self.browser.find_element_by_xpath(x_path).text
  File "/Users/Sheryl/PycharmProjects/Itc_data_mining/data_mining/lib/python3.6/site-packages/selenium/webdriver/remote/webdriver.py", line 394, in find_element_by_xpath
    return self.find_element(by=By.XPATH, value=xpath)
  File "/Users/Sheryl/PycharmProjects/Itc_data_mining/data_mining/lib/python3.6/site-packages/selenium/webdriver/remote/webdriver.py", line 978, in find_element
    'value': value})['value']
  File "/Users/Sheryl/PycharmProjects/Itc_data_mining/data_mining/lib/python3.6/site-packages/selenium/webdriver/remote/webdriver.py", line 321, in execute
    self.error_handler.check_response(response)
  File "/Users/Sheryl/PycharmProjects/Itc_data_mining/data_mining/lib/python3.6/site-packages/selenium/webdriver/remote/errorhandler.py", line 242, in check_response
    raise exception_class(message, screen, stacktrace)
selenium.common.exceptions.NoSuchElementException: Message: Unable to locate element: //div[@class="infoEntity"]//label[text()="Type"]//following-sibling::*

2020-07-20 17:21:36 - root - ERROR - There is a problem with catching text from xpath
Traceback (most recent call last):
  File "/Users/Sheryl/PycharmProjects/Itc_data_mining/scraper.py", line 42, in catch_optional_text_value_by_xpath
    text_value = self.browser.find_element_by_xpath(x_path).text
  File "/Users/Sheryl/PycharmProjects/Itc_data_mining/data_mining/lib/python3.6/site-packages/selenium/webdriver/remote/webdriver.py", line 394, in find_element_by_xpath
    return self.find_element(by=By.XPATH, value=xpath)
  File "/Users/Sheryl/PycharmProjects/Itc_data_mining/data_mining/lib/python3.6/site-packages/selenium/webdriver/remote/webdriver.py", line 978, in find_element
    'value': value})['value']
  File "/Users/Sheryl/PycharmProjects/Itc_data_mining/data_mining/lib/python3.6/site-packages/selenium/webdriver/remote/webdriver.py", line 321, in execute
    self.error_handler.check_response(response)
  File "/Users/Sheryl/PycharmProjects/Itc_data_mining/data_mining/lib/python3.6/site-packages/selenium/webdriver/remote/errorhandler.py", line 242, in check_response
    raise exception_class(message, screen, stacktrace)
selenium.common.exceptions.NoSuchElementException: Message: Unable to locate element: //div[@class="infoEntity"]//label[text()="Revenue"]//following-sibling::*

2020-07-20 17:21:36 - root - ERROR - There is a problem with catching text from xpath
Traceback (most recent call last):
  File "/Users/Sheryl/PycharmProjects/Itc_data_mining/scraper.py", line 42, in catch_optional_text_value_by_xpath
    text_value = self.browser.find_element_by_xpath(x_path).text
  File "/Users/Sheryl/PycharmProjects/Itc_data_mining/data_mining/lib/python3.6/site-packages/selenium/webdriver/remote/webdriver.py", line 394, in find_element_by_xpath
    return self.find_element(by=By.XPATH, value=xpath)
  File "/Users/Sheryl/PycharmProjects/Itc_data_mining/data_mining/lib/python3.6/site-packages/selenium/webdriver/remote/webdriver.py", line 978, in find_element
    'value': value})['value']
  File "/Users/Sheryl/PycharmProjects/Itc_data_mining/data_mining/lib/python3.6/site-packages/selenium/webdriver/remote/webdriver.py", line 321, in execute
    self.error_handler.check_response(response)
  File "/Users/Sheryl/PycharmProjects/Itc_data_mining/data_mining/lib/python3.6/site-packages/selenium/webdriver/remote/errorhandler.py", line 242, in check_response
    raise exception_class(message, screen, stacktrace)
selenium.common.exceptions.NoSuchElementException: Message: Unable to locate element: //div[@class="infoEntity"]//label[text()="Headquarters"]//following-sibling::*

2020-07-20 17:21:36 - root - ERROR - There is a problem with catching text from xpath
Traceback (most recent call last):
  File "/Users/Sheryl/PycharmProjects/Itc_data_mining/scraper.py", line 42, in catch_optional_text_value_by_xpath
    text_value = self.browser.find_element_by_xpath(x_path).text
  File "/Users/Sheryl/PycharmProjects/Itc_data_mining/data_mining/lib/python3.6/site-packages/selenium/webdriver/remote/webdriver.py", line 394, in find_element_by_xpath
    return self.find_element(by=By.XPATH, value=xpath)
  File "/Users/Sheryl/PycharmProjects/Itc_data_mining/data_mining/lib/python3.6/site-packages/selenium/webdriver/remote/webdriver.py", line 978, in find_element
    'value': value})['value']
  File "/Users/Sheryl/PycharmProjects/Itc_data_mining/data_mining/lib/python3.6/site-packages/selenium/webdriver/remote/webdriver.py", line 321, in execute
    self.error_handler.check_response(response)
  File "/Users/Sheryl/PycharmProjects/Itc_data_mining/data_mining/lib/python3.6/site-packages/selenium/webdriver/remote/errorhandler.py", line 242, in check_response
    raise exception_class(message, screen, stacktrace)
selenium.common.exceptions.NoSuchElementException: Message: Unable to locate element: //div[@class="infoEntity"]//label[text()="Competitors"]//following-sibling::*

2020-07-20 17:21:36 - root - INFO - Insert company to DB successfully
2020-07-20 17:21:36 - root - INFO - Insert job to DB successfully
2020-07-20 17:22:06 - root - ERROR - There is a problem with catching text from xpath
Traceback (most recent call last):
  File "/Users/Sheryl/PycharmProjects/Itc_data_mining/scraper.py", line 42, in catch_optional_text_value_by_xpath
    text_value = self.browser.find_element_by_xpath(x_path).text
  File "/Users/Sheryl/PycharmProjects/Itc_data_mining/data_mining/lib/python3.6/site-packages/selenium/webdriver/remote/webdriver.py", line 394, in find_element_by_xpath
    return self.find_element(by=By.XPATH, value=xpath)
  File "/Users/Sheryl/PycharmProjects/Itc_data_mining/data_mining/lib/python3.6/site-packages/selenium/webdriver/remote/webdriver.py", line 978, in find_element
    'value': value})['value']
  File "/Users/Sheryl/PycharmProjects/Itc_data_mining/data_mining/lib/python3.6/site-packages/selenium/webdriver/remote/webdriver.py", line 321, in execute
    self.error_handler.check_response(response)
  File "/Users/Sheryl/PycharmProjects/Itc_data_mining/data_mining/lib/python3.6/site-packages/selenium/webdriver/remote/errorhandler.py", line 242, in check_response
    raise exception_class(message, screen, stacktrace)
selenium.common.exceptions.NoSuchElementException: Message: Unable to locate element: //div[@class="infoEntity"]//label[text()="Founded"]//following-sibling::*

2020-07-20 17:22:06 - root - ERROR - There is a problem with catching text from xpath
Traceback (most recent call last):
  File "/Users/Sheryl/PycharmProjects/Itc_data_mining/scraper.py", line 42, in catch_optional_text_value_by_xpath
    text_value = self.browser.find_element_by_xpath(x_path).text
  File "/Users/Sheryl/PycharmProjects/Itc_data_mining/data_mining/lib/python3.6/site-packages/selenium/webdriver/remote/webdriver.py", line 394, in find_element_by_xpath
    return self.find_element(by=By.XPATH, value=xpath)
  File "/Users/Sheryl/PycharmProjects/Itc_data_mining/data_mining/lib/python3.6/site-packages/selenium/webdriver/remote/webdriver.py", line 978, in find_element
    'value': value})['value']
  File "/Users/Sheryl/PycharmProjects/Itc_data_mining/data_mining/lib/python3.6/site-packages/selenium/webdriver/remote/webdriver.py", line 321, in execute
    self.error_handler.check_response(response)
  File "/Users/Sheryl/PycharmProjects/Itc_data_mining/data_mining/lib/python3.6/site-packages/selenium/webdriver/remote/errorhandler.py", line 242, in check_response
    raise exception_class(message, screen, stacktrace)
selenium.common.exceptions.NoSuchElementException: Message: Unable to locate element: //div[@class="infoEntity"]//label[text()="Industry"]//following-sibling::*

2020-07-20 17:22:06 - root - ERROR - There is a problem with catching text from xpath
Traceback (most recent call last):
  File "/Users/Sheryl/PycharmProjects/Itc_data_mining/scraper.py", line 42, in catch_optional_text_value_by_xpath
    text_value = self.browser.find_element_by_xpath(x_path).text
  File "/Users/Sheryl/PycharmProjects/Itc_data_mining/data_mining/lib/python3.6/site-packages/selenium/webdriver/remote/webdriver.py", line 394, in find_element_by_xpath
    return self.find_element(by=By.XPATH, value=xpath)
  File "/Users/Sheryl/PycharmProjects/Itc_data_mining/data_mining/lib/python3.6/site-packages/selenium/webdriver/remote/webdriver.py", line 978, in find_element
    'value': value})['value']
  File "/Users/Sheryl/PycharmProjects/Itc_data_mining/data_mining/lib/python3.6/site-packages/selenium/webdriver/remote/webdriver.py", line 321, in execute
    self.error_handler.check_response(response)
  File "/Users/Sheryl/PycharmProjects/Itc_data_mining/data_mining/lib/python3.6/site-packages/selenium/webdriver/remote/errorhandler.py", line 242, in check_response
    raise exception_class(message, screen, stacktrace)
selenium.common.exceptions.NoSuchElementException: Message: Unable to locate element: //div[@class="infoEntity"]//label[text()="Sector"]//following-sibling::*

2020-07-20 17:22:06 - root - ERROR - There is a problem with catching text from xpath
Traceback (most recent call last):
  File "/Users/Sheryl/PycharmProjects/Itc_data_mining/scraper.py", line 42, in catch_optional_text_value_by_xpath
    text_value = self.browser.find_element_by_xpath(x_path).text
  File "/Users/Sheryl/PycharmProjects/Itc_data_mining/data_mining/lib/python3.6/site-packages/selenium/webdriver/remote/webdriver.py", line 394, in find_element_by_xpath
    return self.find_element(by=By.XPATH, value=xpath)
  File "/Users/Sheryl/PycharmProjects/Itc_data_mining/data_mining/lib/python3.6/site-packages/selenium/webdriver/remote/webdriver.py", line 978, in find_element
    'value': value})['value']
  File "/Users/Sheryl/PycharmProjects/Itc_data_mining/data_mining/lib/python3.6/site-packages/selenium/webdriver/remote/webdriver.py", line 321, in execute
    self.error_handler.check_response(response)
  File "/Users/Sheryl/PycharmProjects/Itc_data_mining/data_mining/lib/python3.6/site-packages/selenium/webdriver/remote/errorhandler.py", line 242, in check_response
    raise exception_class(message, screen, stacktrace)
selenium.common.exceptions.NoSuchElementException: Message: Unable to locate element: //div[@class="infoEntity"]//label[text()="Competitors"]//following-sibling::*

2020-07-20 17:22:06 - root - INFO - Insert company to DB successfully
2020-07-20 17:22:06 - root - INFO - Insert job to DB successfully
2020-07-20 17:22:36 - root - ERROR - There is a problem with catching text from xpath
Traceback (most recent call last):
  File "/Users/Sheryl/PycharmProjects/Itc_data_mining/scraper.py", line 42, in catch_optional_text_value_by_xpath
    text_value = self.browser.find_element_by_xpath(x_path).text
  File "/Users/Sheryl/PycharmProjects/Itc_data_mining/data_mining/lib/python3.6/site-packages/selenium/webdriver/remote/webdriver.py", line 394, in find_element_by_xpath
    return self.find_element(by=By.XPATH, value=xpath)
  File "/Users/Sheryl/PycharmProjects/Itc_data_mining/data_mining/lib/python3.6/site-packages/selenium/webdriver/remote/webdriver.py", line 978, in find_element
    'value': value})['value']
  File "/Users/Sheryl/PycharmProjects/Itc_data_mining/data_mining/lib/python3.6/site-packages/selenium/webdriver/remote/webdriver.py", line 321, in execute
    self.error_handler.check_response(response)
  File "/Users/Sheryl/PycharmProjects/Itc_data_mining/data_mining/lib/python3.6/site-packages/selenium/webdriver/remote/errorhandler.py", line 242, in check_response
    raise exception_class(message, screen, stacktrace)
selenium.common.exceptions.NoSuchElementException: Message: Unable to locate element: //div[@class="infoEntity"]//label[text()="Founded"]//following-sibling::*

2020-07-20 17:22:36 - root - ERROR - There is a problem with catching text from xpath
Traceback (most recent call last):
  File "/Users/Sheryl/PycharmProjects/Itc_data_mining/scraper.py", line 42, in catch_optional_text_value_by_xpath
    text_value = self.browser.find_element_by_xpath(x_path).text
  File "/Users/Sheryl/PycharmProjects/Itc_data_mining/data_mining/lib/python3.6/site-packages/selenium/webdriver/remote/webdriver.py", line 394, in find_element_by_xpath
    return self.find_element(by=By.XPATH, value=xpath)
  File "/Users/Sheryl/PycharmProjects/Itc_data_mining/data_mining/lib/python3.6/site-packages/selenium/webdriver/remote/webdriver.py", line 978, in find_element
    'value': value})['value']
  File "/Users/Sheryl/PycharmProjects/Itc_data_mining/data_mining/lib/python3.6/site-packages/selenium/webdriver/remote/webdriver.py", line 321, in execute
    self.error_handler.check_response(response)
  File "/Users/Sheryl/PycharmProjects/Itc_data_mining/data_mining/lib/python3.6/site-packages/selenium/webdriver/remote/errorhandler.py", line 242, in check_response
    raise exception_class(message, screen, stacktrace)
selenium.common.exceptions.NoSuchElementException: Message: Unable to locate element: //div[@class="infoEntity"]//label[text()="Industry"]//following-sibling::*

2020-07-20 17:22:36 - root - ERROR - There is a problem with catching text from xpath
Traceback (most recent call last):
  File "/Users/Sheryl/PycharmProjects/Itc_data_mining/scraper.py", line 42, in catch_optional_text_value_by_xpath
    text_value = self.browser.find_element_by_xpath(x_path).text
  File "/Users/Sheryl/PycharmProjects/Itc_data_mining/data_mining/lib/python3.6/site-packages/selenium/webdriver/remote/webdriver.py", line 394, in find_element_by_xpath
    return self.find_element(by=By.XPATH, value=xpath)
  File "/Users/Sheryl/PycharmProjects/Itc_data_mining/data_mining/lib/python3.6/site-packages/selenium/webdriver/remote/webdriver.py", line 978, in find_element
    'value': value})['value']
  File "/Users/Sheryl/PycharmProjects/Itc_data_mining/data_mining/lib/python3.6/site-packages/selenium/webdriver/remote/webdriver.py", line 321, in execute
    self.error_handler.check_response(response)
  File "/Users/Sheryl/PycharmProjects/Itc_data_mining/data_mining/lib/python3.6/site-packages/selenium/webdriver/remote/errorhandler.py", line 242, in check_response
    raise exception_class(message, screen, stacktrace)
selenium.common.exceptions.NoSuchElementException: Message: Unable to locate element: //div[@class="infoEntity"]//label[text()="Sector"]//following-sibling::*

2020-07-20 17:22:36 - root - ERROR - There is a problem with catching text from xpath
Traceback (most recent call last):
  File "/Users/Sheryl/PycharmProjects/Itc_data_mining/scraper.py", line 42, in catch_optional_text_value_by_xpath
    text_value = self.browser.find_element_by_xpath(x_path).text
  File "/Users/Sheryl/PycharmProjects/Itc_data_mining/data_mining/lib/python3.6/site-packages/selenium/webdriver/remote/webdriver.py", line 394, in find_element_by_xpath
    return self.find_element(by=By.XPATH, value=xpath)
  File "/Users/Sheryl/PycharmProjects/Itc_data_mining/data_mining/lib/python3.6/site-packages/selenium/webdriver/remote/webdriver.py", line 978, in find_element
    'value': value})['value']
  File "/Users/Sheryl/PycharmProjects/Itc_data_mining/data_mining/lib/python3.6/site-packages/selenium/webdriver/remote/webdriver.py", line 321, in execute
    self.error_handler.check_response(response)
  File "/Users/Sheryl/PycharmProjects/Itc_data_mining/data_mining/lib/python3.6/site-packages/selenium/webdriver/remote/errorhandler.py", line 242, in check_response
    raise exception_class(message, screen, stacktrace)
selenium.common.exceptions.NoSuchElementException: Message: Unable to locate element: //div[@class="infoEntity"]//label[text()="Competitors"]//following-sibling::*

2020-07-20 17:22:36 - root - INFO - Insert company to DB successfully
2020-07-20 17:22:36 - root - INFO - Insert job to DB successfully
2020-07-20 17:23:04 - root - INFO - Insert company to DB successfully
2020-07-20 17:23:04 - root - INFO - Get information from DB
2020-07-20 17:23:22 - root - INFO - Browser connect to URL
2020-07-20 17:23:22 - root - INFO - Search for competitor's company page
2020-07-20 17:23:22 - root - ERROR - No popup to close
Traceback (most recent call last):
  File "/Users/Sheryl/PycharmProjects/Itc_data_mining/scraper.py", line 28, in close_popup
    pop_up = self.browser.find_element_by_xpath(cst.POP_UP_XPATH)
  File "/Users/Sheryl/PycharmProjects/Itc_data_mining/data_mining/lib/python3.6/site-packages/selenium/webdriver/remote/webdriver.py", line 394, in find_element_by_xpath
    return self.find_element(by=By.XPATH, value=xpath)
  File "/Users/Sheryl/PycharmProjects/Itc_data_mining/data_mining/lib/python3.6/site-packages/selenium/webdriver/remote/webdriver.py", line 978, in find_element
    'value': value})['value']
  File "/Users/Sheryl/PycharmProjects/Itc_data_mining/data_mining/lib/python3.6/site-packages/selenium/webdriver/remote/webdriver.py", line 321, in execute
    self.error_handler.check_response(response)
  File "/Users/Sheryl/PycharmProjects/Itc_data_mining/data_mining/lib/python3.6/site-packages/selenium/webdriver/remote/errorhandler.py", line 242, in check_response
    raise exception_class(message, screen, stacktrace)
selenium.common.exceptions.NoSuchElementException: Message: Unable to locate element: //div[contains(@class,'modal_main')]//span[@class='SVGInline modal_closeIcon']

2020-07-20 17:23:31 - root - INFO - Browser connect to new URL of a company
2020-07-20 17:23:50 - root - INFO - Close browser successfully
2020-07-20 17:23:50 - root - INFO - Insert company to DB successfully
2020-07-20 17:23:50 - root - INFO - Insert competitors to DB successfully
2020-07-20 17:23:50 - root - INFO - Get information from DB
2020-07-20 17:24:03 - root - INFO - Browser connect to URL
2020-07-20 17:24:05 - root - INFO - Search for competitor's company page
2020-07-20 17:24:05 - root - ERROR - No popup to close
Traceback (most recent call last):
  File "/Users/Sheryl/PycharmProjects/Itc_data_mining/scraper.py", line 28, in close_popup
    pop_up = self.browser.find_element_by_xpath(cst.POP_UP_XPATH)
  File "/Users/Sheryl/PycharmProjects/Itc_data_mining/data_mining/lib/python3.6/site-packages/selenium/webdriver/remote/webdriver.py", line 394, in find_element_by_xpath
    return self.find_element(by=By.XPATH, value=xpath)
  File "/Users/Sheryl/PycharmProjects/Itc_data_mining/data_mining/lib/python3.6/site-packages/selenium/webdriver/remote/webdriver.py", line 978, in find_element
    'value': value})['value']
  File "/Users/Sheryl/PycharmProjects/Itc_data_mining/data_mining/lib/python3.6/site-packages/selenium/webdriver/remote/webdriver.py", line 321, in execute
    self.error_handler.check_response(response)
  File "/Users/Sheryl/PycharmProjects/Itc_data_mining/data_mining/lib/python3.6/site-packages/selenium/webdriver/remote/errorhandler.py", line 242, in check_response
    raise exception_class(message, screen, stacktrace)
selenium.common.exceptions.NoSuchElementException: Message: Unable to locate element: //div[contains(@class,'modal_main')]//span[@class='SVGInline modal_closeIcon']

2020-07-20 17:24:13 - root - INFO - Browser connect to new URL of a company
2020-07-20 17:24:36 - root - INFO - Close browser successfully
2020-07-20 17:24:36 - root - INFO - Insert company to DB successfully
2020-07-20 17:24:36 - root - INFO - Insert competitors to DB successfully
2020-07-20 17:24:36 - root - INFO - Insert job to DB successfully
2020-07-20 17:25:06 - root - ERROR - There is a problem with catching text from xpath
Traceback (most recent call last):
  File "/Users/Sheryl/PycharmProjects/Itc_data_mining/scraper.py", line 42, in catch_optional_text_value_by_xpath
    text_value = self.browser.find_element_by_xpath(x_path).text
  File "/Users/Sheryl/PycharmProjects/Itc_data_mining/data_mining/lib/python3.6/site-packages/selenium/webdriver/remote/webdriver.py", line 394, in find_element_by_xpath
    return self.find_element(by=By.XPATH, value=xpath)
  File "/Users/Sheryl/PycharmProjects/Itc_data_mining/data_mining/lib/python3.6/site-packages/selenium/webdriver/remote/webdriver.py", line 978, in find_element
    'value': value})['value']
  File "/Users/Sheryl/PycharmProjects/Itc_data_mining/data_mining/lib/python3.6/site-packages/selenium/webdriver/remote/webdriver.py", line 321, in execute
    self.error_handler.check_response(response)
  File "/Users/Sheryl/PycharmProjects/Itc_data_mining/data_mining/lib/python3.6/site-packages/selenium/webdriver/remote/errorhandler.py", line 242, in check_response
    raise exception_class(message, screen, stacktrace)
selenium.common.exceptions.NoSuchElementException: Message: Unable to locate element: //div[@class="infoEntity"]//label[text()="Founded"]//following-sibling::*

2020-07-20 17:25:06 - root - ERROR - There is a problem with catching text from xpath
Traceback (most recent call last):
  File "/Users/Sheryl/PycharmProjects/Itc_data_mining/scraper.py", line 42, in catch_optional_text_value_by_xpath
    text_value = self.browser.find_element_by_xpath(x_path).text
  File "/Users/Sheryl/PycharmProjects/Itc_data_mining/data_mining/lib/python3.6/site-packages/selenium/webdriver/remote/webdriver.py", line 394, in find_element_by_xpath
    return self.find_element(by=By.XPATH, value=xpath)
  File "/Users/Sheryl/PycharmProjects/Itc_data_mining/data_mining/lib/python3.6/site-packages/selenium/webdriver/remote/webdriver.py", line 978, in find_element
    'value': value})['value']
  File "/Users/Sheryl/PycharmProjects/Itc_data_mining/data_mining/lib/python3.6/site-packages/selenium/webdriver/remote/webdriver.py", line 321, in execute
    self.error_handler.check_response(response)
  File "/Users/Sheryl/PycharmProjects/Itc_data_mining/data_mining/lib/python3.6/site-packages/selenium/webdriver/remote/errorhandler.py", line 242, in check_response
    raise exception_class(message, screen, stacktrace)
selenium.common.exceptions.NoSuchElementException: Message: Unable to locate element: //div[@class="infoEntity"]//label[text()="Industry"]//following-sibling::*

2020-07-20 17:25:06 - root - ERROR - There is a problem with catching text from xpath
Traceback (most recent call last):
  File "/Users/Sheryl/PycharmProjects/Itc_data_mining/scraper.py", line 42, in catch_optional_text_value_by_xpath
    text_value = self.browser.find_element_by_xpath(x_path).text
  File "/Users/Sheryl/PycharmProjects/Itc_data_mining/data_mining/lib/python3.6/site-packages/selenium/webdriver/remote/webdriver.py", line 394, in find_element_by_xpath
    return self.find_element(by=By.XPATH, value=xpath)
  File "/Users/Sheryl/PycharmProjects/Itc_data_mining/data_mining/lib/python3.6/site-packages/selenium/webdriver/remote/webdriver.py", line 978, in find_element
    'value': value})['value']
  File "/Users/Sheryl/PycharmProjects/Itc_data_mining/data_mining/lib/python3.6/site-packages/selenium/webdriver/remote/webdriver.py", line 321, in execute
    self.error_handler.check_response(response)
  File "/Users/Sheryl/PycharmProjects/Itc_data_mining/data_mining/lib/python3.6/site-packages/selenium/webdriver/remote/errorhandler.py", line 242, in check_response
    raise exception_class(message, screen, stacktrace)
selenium.common.exceptions.NoSuchElementException: Message: Unable to locate element: //div[@class="infoEntity"]//label[text()="Sector"]//following-sibling::*

2020-07-20 17:25:06 - root - ERROR - There is a problem with catching text from xpath
Traceback (most recent call last):
  File "/Users/Sheryl/PycharmProjects/Itc_data_mining/scraper.py", line 42, in catch_optional_text_value_by_xpath
    text_value = self.browser.find_element_by_xpath(x_path).text
  File "/Users/Sheryl/PycharmProjects/Itc_data_mining/data_mining/lib/python3.6/site-packages/selenium/webdriver/remote/webdriver.py", line 394, in find_element_by_xpath
    return self.find_element(by=By.XPATH, value=xpath)
  File "/Users/Sheryl/PycharmProjects/Itc_data_mining/data_mining/lib/python3.6/site-packages/selenium/webdriver/remote/webdriver.py", line 978, in find_element
    'value': value})['value']
  File "/Users/Sheryl/PycharmProjects/Itc_data_mining/data_mining/lib/python3.6/site-packages/selenium/webdriver/remote/webdriver.py", line 321, in execute
    self.error_handler.check_response(response)
  File "/Users/Sheryl/PycharmProjects/Itc_data_mining/data_mining/lib/python3.6/site-packages/selenium/webdriver/remote/errorhandler.py", line 242, in check_response
    raise exception_class(message, screen, stacktrace)
selenium.common.exceptions.NoSuchElementException: Message: Unable to locate element: //div[@class="infoEntity"]//label[text()="Competitors"]//following-sibling::*

2020-07-20 17:25:06 - root - INFO - Insert company to DB successfully
2020-07-20 17:25:06 - root - INFO - Insert job to DB successfully
2020-07-20 17:25:37 - root - ERROR - There is a problem with catching text from xpath
Traceback (most recent call last):
  File "/Users/Sheryl/PycharmProjects/Itc_data_mining/scraper.py", line 42, in catch_optional_text_value_by_xpath
    text_value = self.browser.find_element_by_xpath(x_path).text
  File "/Users/Sheryl/PycharmProjects/Itc_data_mining/data_mining/lib/python3.6/site-packages/selenium/webdriver/remote/webdriver.py", line 394, in find_element_by_xpath
    return self.find_element(by=By.XPATH, value=xpath)
  File "/Users/Sheryl/PycharmProjects/Itc_data_mining/data_mining/lib/python3.6/site-packages/selenium/webdriver/remote/webdriver.py", line 978, in find_element
    'value': value})['value']
  File "/Users/Sheryl/PycharmProjects/Itc_data_mining/data_mining/lib/python3.6/site-packages/selenium/webdriver/remote/webdriver.py", line 321, in execute
    self.error_handler.check_response(response)
  File "/Users/Sheryl/PycharmProjects/Itc_data_mining/data_mining/lib/python3.6/site-packages/selenium/webdriver/remote/errorhandler.py", line 242, in check_response
    raise exception_class(message, screen, stacktrace)
selenium.common.exceptions.NoSuchElementException: Message: Unable to locate element: //div[@class="infoEntity"]//label[text()="Competitors"]//following-sibling::*

2020-07-20 17:25:37 - root - INFO - Insert company to DB successfully
2020-07-20 17:25:37 - root - INFO - Insert job to DB successfully
2020-07-20 17:26:06 - root - ERROR - There is a problem with catching text from xpath
Traceback (most recent call last):
  File "/Users/Sheryl/PycharmProjects/Itc_data_mining/scraper.py", line 42, in catch_optional_text_value_by_xpath
    text_value = self.browser.find_element_by_xpath(x_path).text
  File "/Users/Sheryl/PycharmProjects/Itc_data_mining/data_mining/lib/python3.6/site-packages/selenium/webdriver/remote/webdriver.py", line 394, in find_element_by_xpath
    return self.find_element(by=By.XPATH, value=xpath)
  File "/Users/Sheryl/PycharmProjects/Itc_data_mining/data_mining/lib/python3.6/site-packages/selenium/webdriver/remote/webdriver.py", line 978, in find_element
    'value': value})['value']
  File "/Users/Sheryl/PycharmProjects/Itc_data_mining/data_mining/lib/python3.6/site-packages/selenium/webdriver/remote/webdriver.py", line 321, in execute
    self.error_handler.check_response(response)
  File "/Users/Sheryl/PycharmProjects/Itc_data_mining/data_mining/lib/python3.6/site-packages/selenium/webdriver/remote/errorhandler.py", line 242, in check_response
    raise exception_class(message, screen, stacktrace)
selenium.common.exceptions.NoSuchElementException: Message: Unable to locate element: //div[@class="infoEntity"]//label[text()="Founded"]//following-sibling::*

2020-07-20 17:26:06 - root - ERROR - There is a problem with catching text from xpath
Traceback (most recent call last):
  File "/Users/Sheryl/PycharmProjects/Itc_data_mining/scraper.py", line 42, in catch_optional_text_value_by_xpath
    text_value = self.browser.find_element_by_xpath(x_path).text
  File "/Users/Sheryl/PycharmProjects/Itc_data_mining/data_mining/lib/python3.6/site-packages/selenium/webdriver/remote/webdriver.py", line 394, in find_element_by_xpath
    return self.find_element(by=By.XPATH, value=xpath)
  File "/Users/Sheryl/PycharmProjects/Itc_data_mining/data_mining/lib/python3.6/site-packages/selenium/webdriver/remote/webdriver.py", line 978, in find_element
    'value': value})['value']
  File "/Users/Sheryl/PycharmProjects/Itc_data_mining/data_mining/lib/python3.6/site-packages/selenium/webdriver/remote/webdriver.py", line 321, in execute
    self.error_handler.check_response(response)
  File "/Users/Sheryl/PycharmProjects/Itc_data_mining/data_mining/lib/python3.6/site-packages/selenium/webdriver/remote/errorhandler.py", line 242, in check_response
    raise exception_class(message, screen, stacktrace)
selenium.common.exceptions.NoSuchElementException: Message: Unable to locate element: //div[@class="infoEntity"]//label[text()="Industry"]//following-sibling::*

2020-07-20 17:26:06 - root - ERROR - There is a problem with catching text from xpath
Traceback (most recent call last):
  File "/Users/Sheryl/PycharmProjects/Itc_data_mining/scraper.py", line 42, in catch_optional_text_value_by_xpath
    text_value = self.browser.find_element_by_xpath(x_path).text
  File "/Users/Sheryl/PycharmProjects/Itc_data_mining/data_mining/lib/python3.6/site-packages/selenium/webdriver/remote/webdriver.py", line 394, in find_element_by_xpath
    return self.find_element(by=By.XPATH, value=xpath)
  File "/Users/Sheryl/PycharmProjects/Itc_data_mining/data_mining/lib/python3.6/site-packages/selenium/webdriver/remote/webdriver.py", line 978, in find_element
    'value': value})['value']
  File "/Users/Sheryl/PycharmProjects/Itc_data_mining/data_mining/lib/python3.6/site-packages/selenium/webdriver/remote/webdriver.py", line 321, in execute
    self.error_handler.check_response(response)
  File "/Users/Sheryl/PycharmProjects/Itc_data_mining/data_mining/lib/python3.6/site-packages/selenium/webdriver/remote/errorhandler.py", line 242, in check_response
    raise exception_class(message, screen, stacktrace)
selenium.common.exceptions.NoSuchElementException: Message: Unable to locate element: //div[@class="infoEntity"]//label[text()="Sector"]//following-sibling::*

2020-07-20 17:26:06 - root - ERROR - There is a problem with catching text from xpath
Traceback (most recent call last):
  File "/Users/Sheryl/PycharmProjects/Itc_data_mining/scraper.py", line 42, in catch_optional_text_value_by_xpath
    text_value = self.browser.find_element_by_xpath(x_path).text
  File "/Users/Sheryl/PycharmProjects/Itc_data_mining/data_mining/lib/python3.6/site-packages/selenium/webdriver/remote/webdriver.py", line 394, in find_element_by_xpath
    return self.find_element(by=By.XPATH, value=xpath)
  File "/Users/Sheryl/PycharmProjects/Itc_data_mining/data_mining/lib/python3.6/site-packages/selenium/webdriver/remote/webdriver.py", line 978, in find_element
    'value': value})['value']
  File "/Users/Sheryl/PycharmProjects/Itc_data_mining/data_mining/lib/python3.6/site-packages/selenium/webdriver/remote/webdriver.py", line 321, in execute
    self.error_handler.check_response(response)
  File "/Users/Sheryl/PycharmProjects/Itc_data_mining/data_mining/lib/python3.6/site-packages/selenium/webdriver/remote/errorhandler.py", line 242, in check_response
    raise exception_class(message, screen, stacktrace)
selenium.common.exceptions.NoSuchElementException: Message: Unable to locate element: //div[@class="infoEntity"]//label[text()="Competitors"]//following-sibling::*

2020-07-20 17:26:06 - root - INFO - Insert company to DB successfully
2020-07-20 17:26:06 - root - INFO - Insert job to DB successfully
2020-07-20 17:26:35 - root - ERROR - There is a problem with catching text from xpath
Traceback (most recent call last):
  File "/Users/Sheryl/PycharmProjects/Itc_data_mining/scraper.py", line 42, in catch_optional_text_value_by_xpath
    text_value = self.browser.find_element_by_xpath(x_path).text
  File "/Users/Sheryl/PycharmProjects/Itc_data_mining/data_mining/lib/python3.6/site-packages/selenium/webdriver/remote/webdriver.py", line 394, in find_element_by_xpath
    return self.find_element(by=By.XPATH, value=xpath)
  File "/Users/Sheryl/PycharmProjects/Itc_data_mining/data_mining/lib/python3.6/site-packages/selenium/webdriver/remote/webdriver.py", line 978, in find_element
    'value': value})['value']
  File "/Users/Sheryl/PycharmProjects/Itc_data_mining/data_mining/lib/python3.6/site-packages/selenium/webdriver/remote/webdriver.py", line 321, in execute
    self.error_handler.check_response(response)
  File "/Users/Sheryl/PycharmProjects/Itc_data_mining/data_mining/lib/python3.6/site-packages/selenium/webdriver/remote/errorhandler.py", line 242, in check_response
    raise exception_class(message, screen, stacktrace)
selenium.common.exceptions.NoSuchElementException: Message: Unable to locate element: //div[@class="infoEntity"]//label[text()="Size"]//following-sibling::*

2020-07-20 17:26:35 - root - ERROR - There is a problem with catching text from xpath
Traceback (most recent call last):
  File "/Users/Sheryl/PycharmProjects/Itc_data_mining/scraper.py", line 42, in catch_optional_text_value_by_xpath
    text_value = self.browser.find_element_by_xpath(x_path).text
  File "/Users/Sheryl/PycharmProjects/Itc_data_mining/data_mining/lib/python3.6/site-packages/selenium/webdriver/remote/webdriver.py", line 394, in find_element_by_xpath
    return self.find_element(by=By.XPATH, value=xpath)
  File "/Users/Sheryl/PycharmProjects/Itc_data_mining/data_mining/lib/python3.6/site-packages/selenium/webdriver/remote/webdriver.py", line 978, in find_element
    'value': value})['value']
  File "/Users/Sheryl/PycharmProjects/Itc_data_mining/data_mining/lib/python3.6/site-packages/selenium/webdriver/remote/webdriver.py", line 321, in execute
    self.error_handler.check_response(response)
  File "/Users/Sheryl/PycharmProjects/Itc_data_mining/data_mining/lib/python3.6/site-packages/selenium/webdriver/remote/errorhandler.py", line 242, in check_response
    raise exception_class(message, screen, stacktrace)
selenium.common.exceptions.NoSuchElementException: Message: Unable to locate element: //div[@class="infoEntity"]//label[text()="Founded"]//following-sibling::*

2020-07-20 17:26:35 - root - ERROR - There is a problem with catching text from xpath
Traceback (most recent call last):
  File "/Users/Sheryl/PycharmProjects/Itc_data_mining/scraper.py", line 42, in catch_optional_text_value_by_xpath
    text_value = self.browser.find_element_by_xpath(x_path).text
  File "/Users/Sheryl/PycharmProjects/Itc_data_mining/data_mining/lib/python3.6/site-packages/selenium/webdriver/remote/webdriver.py", line 394, in find_element_by_xpath
    return self.find_element(by=By.XPATH, value=xpath)
  File "/Users/Sheryl/PycharmProjects/Itc_data_mining/data_mining/lib/python3.6/site-packages/selenium/webdriver/remote/webdriver.py", line 978, in find_element
    'value': value})['value']
  File "/Users/Sheryl/PycharmProjects/Itc_data_mining/data_mining/lib/python3.6/site-packages/selenium/webdriver/remote/webdriver.py", line 321, in execute
    self.error_handler.check_response(response)
  File "/Users/Sheryl/PycharmProjects/Itc_data_mining/data_mining/lib/python3.6/site-packages/selenium/webdriver/remote/errorhandler.py", line 242, in check_response
    raise exception_class(message, screen, stacktrace)
selenium.common.exceptions.NoSuchElementException: Message: Unable to locate element: //div[@class="infoEntity"]//label[text()="Industry"]//following-sibling::*

2020-07-20 17:26:35 - root - ERROR - There is a problem with catching text from xpath
Traceback (most recent call last):
  File "/Users/Sheryl/PycharmProjects/Itc_data_mining/scraper.py", line 42, in catch_optional_text_value_by_xpath
    text_value = self.browser.find_element_by_xpath(x_path).text
  File "/Users/Sheryl/PycharmProjects/Itc_data_mining/data_mining/lib/python3.6/site-packages/selenium/webdriver/remote/webdriver.py", line 394, in find_element_by_xpath
    return self.find_element(by=By.XPATH, value=xpath)
  File "/Users/Sheryl/PycharmProjects/Itc_data_mining/data_mining/lib/python3.6/site-packages/selenium/webdriver/remote/webdriver.py", line 978, in find_element
    'value': value})['value']
  File "/Users/Sheryl/PycharmProjects/Itc_data_mining/data_mining/lib/python3.6/site-packages/selenium/webdriver/remote/webdriver.py", line 321, in execute
    self.error_handler.check_response(response)
  File "/Users/Sheryl/PycharmProjects/Itc_data_mining/data_mining/lib/python3.6/site-packages/selenium/webdriver/remote/errorhandler.py", line 242, in check_response
    raise exception_class(message, screen, stacktrace)
selenium.common.exceptions.NoSuchElementException: Message: Unable to locate element: //div[@class="infoEntity"]//label[text()="Sector"]//following-sibling::*

2020-07-20 17:26:35 - root - ERROR - There is a problem with catching text from xpath
Traceback (most recent call last):
  File "/Users/Sheryl/PycharmProjects/Itc_data_mining/scraper.py", line 42, in catch_optional_text_value_by_xpath
    text_value = self.browser.find_element_by_xpath(x_path).text
  File "/Users/Sheryl/PycharmProjects/Itc_data_mining/data_mining/lib/python3.6/site-packages/selenium/webdriver/remote/webdriver.py", line 394, in find_element_by_xpath
    return self.find_element(by=By.XPATH, value=xpath)
  File "/Users/Sheryl/PycharmProjects/Itc_data_mining/data_mining/lib/python3.6/site-packages/selenium/webdriver/remote/webdriver.py", line 978, in find_element
    'value': value})['value']
  File "/Users/Sheryl/PycharmProjects/Itc_data_mining/data_mining/lib/python3.6/site-packages/selenium/webdriver/remote/webdriver.py", line 321, in execute
    self.error_handler.check_response(response)
  File "/Users/Sheryl/PycharmProjects/Itc_data_mining/data_mining/lib/python3.6/site-packages/selenium/webdriver/remote/errorhandler.py", line 242, in check_response
    raise exception_class(message, screen, stacktrace)
selenium.common.exceptions.NoSuchElementException: Message: Unable to locate element: //div[@class="infoEntity"]//label[text()="Type"]//following-sibling::*

2020-07-20 17:26:35 - root - ERROR - There is a problem with catching text from xpath
Traceback (most recent call last):
  File "/Users/Sheryl/PycharmProjects/Itc_data_mining/scraper.py", line 42, in catch_optional_text_value_by_xpath
    text_value = self.browser.find_element_by_xpath(x_path).text
  File "/Users/Sheryl/PycharmProjects/Itc_data_mining/data_mining/lib/python3.6/site-packages/selenium/webdriver/remote/webdriver.py", line 394, in find_element_by_xpath
    return self.find_element(by=By.XPATH, value=xpath)
  File "/Users/Sheryl/PycharmProjects/Itc_data_mining/data_mining/lib/python3.6/site-packages/selenium/webdriver/remote/webdriver.py", line 978, in find_element
    'value': value})['value']
  File "/Users/Sheryl/PycharmProjects/Itc_data_mining/data_mining/lib/python3.6/site-packages/selenium/webdriver/remote/webdriver.py", line 321, in execute
    self.error_handler.check_response(response)
  File "/Users/Sheryl/PycharmProjects/Itc_data_mining/data_mining/lib/python3.6/site-packages/selenium/webdriver/remote/errorhandler.py", line 242, in check_response
    raise exception_class(message, screen, stacktrace)
selenium.common.exceptions.NoSuchElementException: Message: Unable to locate element: //div[@class="infoEntity"]//label[text()="Revenue"]//following-sibling::*

2020-07-20 17:26:35 - root - ERROR - There is a problem with catching text from xpath
Traceback (most recent call last):
  File "/Users/Sheryl/PycharmProjects/Itc_data_mining/scraper.py", line 42, in catch_optional_text_value_by_xpath
    text_value = self.browser.find_element_by_xpath(x_path).text
  File "/Users/Sheryl/PycharmProjects/Itc_data_mining/data_mining/lib/python3.6/site-packages/selenium/webdriver/remote/webdriver.py", line 394, in find_element_by_xpath
    return self.find_element(by=By.XPATH, value=xpath)
  File "/Users/Sheryl/PycharmProjects/Itc_data_mining/data_mining/lib/python3.6/site-packages/selenium/webdriver/remote/webdriver.py", line 978, in find_element
    'value': value})['value']
  File "/Users/Sheryl/PycharmProjects/Itc_data_mining/data_mining/lib/python3.6/site-packages/selenium/webdriver/remote/webdriver.py", line 321, in execute
    self.error_handler.check_response(response)
  File "/Users/Sheryl/PycharmProjects/Itc_data_mining/data_mining/lib/python3.6/site-packages/selenium/webdriver/remote/errorhandler.py", line 242, in check_response
    raise exception_class(message, screen, stacktrace)
selenium.common.exceptions.NoSuchElementException: Message: Unable to locate element: //div[@class="infoEntity"]//label[text()="Headquarters"]//following-sibling::*

2020-07-20 17:26:35 - root - ERROR - There is a problem with catching text from xpath
Traceback (most recent call last):
  File "/Users/Sheryl/PycharmProjects/Itc_data_mining/scraper.py", line 42, in catch_optional_text_value_by_xpath
    text_value = self.browser.find_element_by_xpath(x_path).text
  File "/Users/Sheryl/PycharmProjects/Itc_data_mining/data_mining/lib/python3.6/site-packages/selenium/webdriver/remote/webdriver.py", line 394, in find_element_by_xpath
    return self.find_element(by=By.XPATH, value=xpath)
  File "/Users/Sheryl/PycharmProjects/Itc_data_mining/data_mining/lib/python3.6/site-packages/selenium/webdriver/remote/webdriver.py", line 978, in find_element
    'value': value})['value']
  File "/Users/Sheryl/PycharmProjects/Itc_data_mining/data_mining/lib/python3.6/site-packages/selenium/webdriver/remote/webdriver.py", line 321, in execute
    self.error_handler.check_response(response)
  File "/Users/Sheryl/PycharmProjects/Itc_data_mining/data_mining/lib/python3.6/site-packages/selenium/webdriver/remote/errorhandler.py", line 242, in check_response
    raise exception_class(message, screen, stacktrace)
selenium.common.exceptions.NoSuchElementException: Message: Unable to locate element: //div[@class="infoEntity"]//label[text()="Competitors"]//following-sibling::*

2020-07-20 17:26:35 - root - INFO - Insert company to DB successfully
2020-07-20 17:26:35 - root - INFO - Insert job to DB successfully
2020-07-20 17:27:05 - root - ERROR - There is a problem with catching text from xpath
Traceback (most recent call last):
  File "/Users/Sheryl/PycharmProjects/Itc_data_mining/scraper.py", line 42, in catch_optional_text_value_by_xpath
    text_value = self.browser.find_element_by_xpath(x_path).text
  File "/Users/Sheryl/PycharmProjects/Itc_data_mining/data_mining/lib/python3.6/site-packages/selenium/webdriver/remote/webdriver.py", line 394, in find_element_by_xpath
    return self.find_element(by=By.XPATH, value=xpath)
  File "/Users/Sheryl/PycharmProjects/Itc_data_mining/data_mining/lib/python3.6/site-packages/selenium/webdriver/remote/webdriver.py", line 978, in find_element
    'value': value})['value']
  File "/Users/Sheryl/PycharmProjects/Itc_data_mining/data_mining/lib/python3.6/site-packages/selenium/webdriver/remote/webdriver.py", line 321, in execute
    self.error_handler.check_response(response)
  File "/Users/Sheryl/PycharmProjects/Itc_data_mining/data_mining/lib/python3.6/site-packages/selenium/webdriver/remote/errorhandler.py", line 242, in check_response
    raise exception_class(message, screen, stacktrace)
selenium.common.exceptions.NoSuchElementException: Message: Unable to locate element: //div[@class="infoEntity"]//label[text()="Competitors"]//following-sibling::*

2020-07-20 17:27:05 - root - INFO - Insert company to DB successfully
2020-07-20 17:27:05 - root - INFO - Insert job to DB successfully
2020-07-20 17:27:35 - root - ERROR - There is a problem with catching text from xpath
Traceback (most recent call last):
  File "/Users/Sheryl/PycharmProjects/Itc_data_mining/scraper.py", line 42, in catch_optional_text_value_by_xpath
    text_value = self.browser.find_element_by_xpath(x_path).text
  File "/Users/Sheryl/PycharmProjects/Itc_data_mining/data_mining/lib/python3.6/site-packages/selenium/webdriver/remote/webdriver.py", line 394, in find_element_by_xpath
    return self.find_element(by=By.XPATH, value=xpath)
  File "/Users/Sheryl/PycharmProjects/Itc_data_mining/data_mining/lib/python3.6/site-packages/selenium/webdriver/remote/webdriver.py", line 978, in find_element
    'value': value})['value']
  File "/Users/Sheryl/PycharmProjects/Itc_data_mining/data_mining/lib/python3.6/site-packages/selenium/webdriver/remote/webdriver.py", line 321, in execute
    self.error_handler.check_response(response)
  File "/Users/Sheryl/PycharmProjects/Itc_data_mining/data_mining/lib/python3.6/site-packages/selenium/webdriver/remote/errorhandler.py", line 242, in check_response
    raise exception_class(message, screen, stacktrace)
selenium.common.exceptions.NoSuchElementException: Message: Unable to locate element: //div[@class="infoEntity"]//label[text()="Competitors"]//following-sibling::*

2020-07-20 17:27:35 - root - INFO - Insert company to DB successfully
2020-07-20 17:27:35 - root - INFO - Insert job to DB successfully
2020-07-20 17:28:04 - root - INFO - Insert company to DB successfully
2020-07-20 17:28:04 - root - INFO - Get information from DB
